Workbook

Sheet try LAP JULI
A1: LAPORAN PENJUALAN BULANAN | AP1: 45839
A2: NAMA BARANG | B2: STOK AWAL | C2: =UPPER("HARI / BULAN : " & TEXT(AP1, "MMMM YYYY")) -> HARI / BULAN : JULI 2025
C3: =TEXT(C4,"dddd") -> Selasa | D3: =TEXT(D4,"dddd") -> Rabu | E3: =TEXT(E4,"dddd") -> Kamis | F3: =TEXT(F4,"dddd") -> Jumat | G3: =TEXT(G4,"dddd") -> Sabtu | H3: =TEXT(H4,"dddd") -> Minggu | I3: =TEXT(I4,"dddd") -> Senin | J3: =TEXT(J4,"dddd") -> Selasa | ... AG3: =TEXT(AG4,"dddd") -> Kamis | AH3: TOTAL | AI3: STOCK | AJ3: SYSTEM | AK3: KET/SELISIH | AL3: HARGA BELI | AM3: HARGA JUAL | AN3: OMSET | AO3: PROFIT
C4: =AP1 -> 45839 | D4: =IF(AND(MONTH(C4+1) = MONTH(C4), C4<>""),C4 + 1, "") -> 45840 | E4: =IF(AND(MONTH(D4+1) = MONTH(D4), D4<>""),D4 + 1, "") -> 45841 | F4: =IF(AND(MONTH(E4+1) = MONTH(E4), E4<>""),E4 + 1, "") -> 45842 | G4: =IF(AND(MONTH(F4+1) = MONTH(F4), F4<>""),F4 + 1, "") -> 45843 | H4: =IF(AND(MONTH(G4+1) = MONTH(G4), G4<>""),G4 + 1, "") -> 45844 | I4: =IF(AND(MONTH(H4+1) = MONTH(H4), H4<>""),H4 + 1, "") -> 45845 | J4: =IF(AND(MONTH(I4+1) = MONTH(I4), I4<>""),I4 + 1, "") -> 45846 | K4: =IF(AND(MONTH(J4+1) = MONTH(J4), J4<>""),J4 + 1, "") -> 45847 | ... AG4: =IF(AND(MONTH(AF4+1) = MONTH(AF4), AF4<>""),AF4 + 1, "") -> 45869
A5: ='MASTER STOCK'!F2 -> Fitting Gantung | B5: ='MASTER STOCK'!G2 -> 12 | AH5: =SUM(C5:AG5) -> 0 | AI5: =B5-SUM(C5:AG5) -> 12 | AJ5: =B5-AH5 -> 12 | AK5: =AJ5-AI5 -> 0 | AL5: ='MASTER STOCK'!I2 -> 1400 | AM5: ='MASTER STOCK'!L2 -> 1820 | AN5: =AH5*AM5 -> 0 | AO5: =(AH5*AM5)-(AH5*AL5) -> 0
A6: ='MASTER STOCK'!F3 -> Colokan T | B6: ='MASTER STOCK'!G3 -> 12 | AH6: =SUM(C6:AG6) -> 0 | AI6: =B6-SUM(C6:AG6) -> 12 | AJ6: =B6-AH6 -> 12 | AK6: =AJ6-AI6 -> 0 | AL6: ='MASTER STOCK'!I3 -> 3000 | AM6: ='MASTER STOCK'!L3 -> 3900 | AN6: =AH6*AM6 -> 0 | AO6: =(AH6*AM6)-(AH6*AL6) -> 0
A7: ='MASTER STOCK'!F4 -> Steker Bulat | B7: ='MASTER STOCK'!G4 -> 12 | AH7: =SUM(C7:AG7) -> 0 | AI7: =B7-SUM(C7:AG7) -> 12 | AJ7: =B7-AH7 -> 12 | AK7: =AJ7-AI7 -> 0 | AL7: ='MASTER STOCK'!I4 -> 3000 | AM7: ='MASTER STOCK'!L4 -> 6000 | AN7: =AH7*AM7 -> 0 | AO7: =(AH7*AM7)-(AH7*AL7) -> 0
A8: ='MASTER STOCK'!F5 -> Steker Gepeng | B8: ='MASTER STOCK'!G5 -> 12 | AH8: =SUM(C8:AG8) -> 0 | AI8: =B8-SUM(C8:AG8) -> 12 | AJ8: =B8-AH8 -> 12 | AK8: =AJ8-AI8 -> 0 | AL8: ='MASTER STOCK'!I5 -> 1100 | AM8: ='MASTER STOCK'!L5 -> 1430 | AN8: =AH8*AM8 -> 0 | AO8: =(AH8*AM8)-(AH8*AL8) -> 0
A9: ='MASTER STOCK'!F6 -> Saklar Gantung Putih jumbo | B9: ='MASTER STOCK'!G6 -> 12 | AH9: =SUM(C9:AG9) -> 0 | AI9: =B9-SUM(C9:AG9) -> 12 | AJ9: =B9-AH9 -> 12 | AK9: =AJ9-AI9 -> 0 | AL9: ='MASTER STOCK'!I6 -> 2250 | AM9: ='MASTER STOCK'!L6 -> 4000 | AN9: =AH9*AM9 -> 0 | AO9: =(AH9*AM9)-(AH9*AL9) -> 0
A10: ='MASTER STOCK'!F7 -> Saklar Gantung Hitam | B10: ='MASTER STOCK'!G7 -> 12 | AH10: =SUM(C10:AG10) -> 0 | AI10: =B10-SUM(C10:AG10) -> 12 | AJ10: =B10-AH10 -> 12 | AK10: =AJ10-AI10 -> 0 | AL10: ='MASTER STOCK'!I7 -> 1850 | AM10: ='MASTER STOCK'!L7 -> 4000 | AN10: =AH10*AM10 -> 0 | AO10: =(AH10*AM10)-(AH10*AL10) -> 0
A11: ='MASTER STOCK'!F8 -> Isolasi Hitam National | B11: ='MASTER STOCK'!G8 -> 20 | AH11: =SUM(C11:AG11) -> 0 | AI11: =B11-SUM(C11:AG11) -> 20 | AJ11: =B11-AH11 -> 20 | AK11: =AJ11-AI11 -> 0 | AL11: ='MASTER STOCK'!I8 -> 5150 | AM11: ='MASTER STOCK'!L8 -> 7982.5 | AN11: =AH11*AM11 -> 0 | AO11: =(AH11*AM11)-(AH11*AL11) -> 0
A12: ='MASTER STOCK'!F9 -> Lem PVC Isarplas 40gram | B12: ='MASTER STOCK'!G9 -> 24 | AH12: =SUM(C12:AG12) -> 0 | AI12: =B12-SUM(C12:AG12) -> 24 | AJ12: =B12-AH12 -> 24 | AK12: =AJ12-AI12 -> 0 | AL12: ='MASTER STOCK'!I9 -> 6900 | AM12: ='MASTER STOCK'!L9 -> 9500 | AN12: =AH12*AM12 -> 0 | AO12: =(AH12*AM12)-(AH12*AL12) -> 0
A13: ='MASTER STOCK'!F10 -> Isolasi Kran air onda | B13: ='MASTER STOCK'!G10 -> 60 | AH13: =SUM(C13:AG13) -> 0 | AI13: =B13-SUM(C13:AG13) -> 60 | AJ13: =B13-AH13 -> 60 | AK13: =AJ13-AI13 -> 0 | AL13: ='MASTER STOCK'!I10 -> 1150 | AM13: ='MASTER STOCK'!L10 -> 1495 | AN13: =AH13*AM13 -> 0 | AO13: =(AH13*AM13)-(AH13*AL13) -> 0
A14: ='MASTER STOCK'!F11 -> Tutup Pipa 3/4" | B14: ='MASTER STOCK'!G11 -> 50 | AH14: =SUM(C14:AG14) -> 0 | AI14: =B14-SUM(C14:AG14) -> 50 | AJ14: =B14-AH14 -> 50 | AK14: =AJ14-AI14 -> 0 | AL14: ='MASTER STOCK'!I11 -> 850 | AM14: ='MASTER STOCK'!L11 -> 1275 | AN14: =AH14*AM14 -> 0 | AO14: =(AH14*AM14)-(AH14*AL14) -> 0
A15: ='MASTER STOCK'!F12 -> Fitting lampu gantung outdoor (10 m 5 fitting) | B15: ='MASTER STOCK'!G12 -> 1 | AH15: =SUM(C15:AG15) -> 0 | AI15: =B15-SUM(C15:AG15) -> 1 | AJ15: =B15-AH15 -> 1 | AK15: =AJ15-AI15 -> 0 | AL15: ='MASTER STOCK'!I12 -> 38000 | AM15: ='MASTER STOCK'!L12 -> 49400 | AN15: =AH15*AM15 -> 0 | AO15: =(AH15*AM15)-(AH15*AL15) -> 0
A16: ='MASTER STOCK'!F13 -> Obeng karet 4" plus | B16: ='MASTER STOCK'!G13 -> 5 | AH16: =SUM(C16:AG16) -> 0 | AI16: =B16-SUM(C16:AG16) -> 5 | AJ16: =B16-AH16 -> 5 | AK16: =AJ16-AI16 -> 0 | AL16: ='MASTER STOCK'!I13 -> 5500 | AM16: ='MASTER STOCK'!L13 -> 7150 | AN16: =AH16*AM16 -> 0 | AO16: =(AH16*AM16)-(AH16*AL16) -> 0
A17: ='MASTER STOCK'!F14 -> Obeng karet 4" minus | B17: ='MASTER STOCK'!G14 -> 5 | S17: 1 | AH17: =SUM(C17:AG17) -> 1 | AI17: =B17-SUM(C17:AG17) -> 4 | AJ17: =B17-AH17 -> 4 | AK17: =AJ17-AI17 -> 0 | AL17: ='MASTER STOCK'!I14 -> 5500 | AM17: ='MASTER STOCK'!L14 -> 7150 | AN17: =AH17*AM17 -> 7150 | AO17: =(AH17*AM17)-(AH17*AL17) -> 1650
A18: ='MASTER STOCK'!F15 -> Obeng karet 6" plus | B18: ='MASTER STOCK'!G15 -> 5 | AH18: =SUM(C18:AG18) -> 0 | AI18: =B18-SUM(C18:AG18) -> 5 | AJ18: =B18-AH18 -> 5 | AK18: =AJ18-AI18 -> 0 | AL18: ='MASTER STOCK'!I15 -> 7000 | AM18: ='MASTER STOCK'!L15 -> 9100 | AN18: =AH18*AM18 -> 0 | AO18: =(AH18*AM18)-(AH18*AL18) -> 0
A19: ='MASTER STOCK'!F16 -> Obeng karet 6" Minus | B19: ='MASTER STOCK'!G16 -> 5 | AH19: =SUM(C19:AG19) -> 0 | AI19: =B19-SUM(C19:AG19) -> 5 | AJ19: =B19-AH19 -> 5 | AK19: =AJ19-AI19 -> 0 | AL19: ='MASTER STOCK'!I16 -> 7000 | AM19: ='MASTER STOCK'!L16 -> 9100 | AN19: =AH19*AM19 -> 0 | AO19: =(AH19*AM19)-(AH19*AL19) -> 0
A20: ='MASTER STOCK'!F17 -> Kabel Awg 24 Double 2x18 merah hitam | B20: ='MASTER STOCK'!G17 -> 2 | AH20: =SUM(C20:AG20) -> 0 | AI20: =B20-SUM(C20:AG20) -> 2 | AJ20: =B20-AH20 -> 2 | AK20: =AJ20-AI20 -> 0 | AL20: ='MASTER STOCK'!I17 -> 106500 | AM20: ='MASTER STOCK'!L17 -> 181050 | AN20: =AH20*AM20 -> 0 | AO20: =(AH20*AM20)-(AH20*AL20) -> 0
A21: ='MASTER STOCK'!F18 -> Kabel bintik serabut tembaga motor mobil 20mx0.5mm/0,85mm merah 0,5mm | B21: ='MASTER STOCK'!G18 -> 2 | AH21: =SUM(C21:AG21) -> 0 | AI21: =B21-SUM(C21:AG21) -> 2 | AJ21: =B21-AH21 -> 2 | AK21: =AJ21-AI21 -> 0 | AL21: ='MASTER STOCK'!I18 -> 33700 | AM21: ='MASTER STOCK'!L18 -> 57290 | AN21: =AH21*AM21 -> 0 | AO21: =(AH21*AM21)-(AH21*AL21) -> 0
A22: ='MASTER STOCK'!F19 -> Kabel bintik serabut tembaga motor mobil 20mx0.5mm/0,85mm hitam 0,5mm | B22: ='MASTER STOCK'!G19 -> 2 | AH22: =SUM(C22:AG22) -> 0 | AI22: =B22-SUM(C22:AG22) -> 2 | AJ22: =B22-AH22 -> 2 | AK22: =AJ22-AI22 -> 0 | AL22: ='MASTER STOCK'!I19 -> 33700 | AM22: ='MASTER STOCK'!L19 -> 57290 | AN22: =AH22*AM22 -> 0 | AO22: =(AH22*AM22)-(AH22*AL22) -> 0
A23: ='MASTER STOCK'!F20 -> Mata Gerinda keramik 4 inch kering | B23: ='MASTER STOCK'!G20 -> 5 | AH23: =SUM(C23:AG23) -> 0 | AI23: =B23-SUM(C23:AG23) -> 5 | AJ23: =B23-AH23 -> 5 | AK23: =AJ23-AI23 -> 0 | AL23: ='MASTER STOCK'!I20 -> 12000 | AM23: ='MASTER STOCK'!L20 -> 18000 | AN23: =AH23*AM23 -> 0 | AO23: =(AH23*AM23)-(AH23*AL23) -> 0
A24: ='MASTER STOCK'!F21 -> Kabel tunggal serabut 0.8mmx25m biru 25m | B24: ='MASTER STOCK'!G21 -> 1 | AH24: =SUM(C24:AG24) -> 0 | AI24: =B24-SUM(C24:AG24) -> 1 | AJ24: =B24-AH24 -> 1 | AK24: =AJ24-AI24 -> 0 | AL24: ='MASTER STOCK'!I21 -> 17500 | AM24: ='MASTER STOCK'!L21 -> 29750 | AN24: =AH24*AM24 -> 0 | AO24: =(AH24*AM24)-(AH24*AL24) -> 0
A25: ='MASTER STOCK'!F22 -> Kabel tunggal serabut 0.8mmx25m Hitam 25m | B25: ='MASTER STOCK'!G22 -> 1 | AH25: =SUM(C25:AG25) -> 0 | AI25: =B25-SUM(C25:AG25) -> 1 | AJ25: =B25-AH25 -> 1 | AK25: =AJ25-AI25 -> 0 | AL25: ='MASTER STOCK'!I22 -> 17500 | AM25: ='MASTER STOCK'!L22 -> 29750 | AN25: =AH25*AM25 -> 0 | AO25: =(AH25*AM25)-(AH25*AL25) -> 0
A26: ='MASTER STOCK'!F23 -> Lampu Hias LED strip USB 10m+adaptor | B26: ='MASTER STOCK'!G23 -> 2 | AH26: =SUM(C26:AG26) -> 0 | AI26: =B26-SUM(C26:AG26) -> 2 | AJ26: =B26-AH26 -> 2 | AK26: =AJ26-AI26 -> 0 | AL26: ='MASTER STOCK'!I23 -> 50000 | AM26: ='MASTER STOCK'!L23 -> 65000 | AN26: =AH26*AM26 -> 0 | AO26: =(AH26*AM26)-(AH26*AL26) -> 0
A27: ='MASTER STOCK'!F24 -> Lampu LED strip outdoor rainbow 10m +adaptor | B27: ='MASTER STOCK'!G24 -> 5 | AH27: =SUM(C27:AG27) -> 0 | AI27: =B27-SUM(C27:AG27) -> 5 | AJ27: =B27-AH27 -> 5 | AK27: =AJ27-AI27 -> 0 | AL27: ='MASTER STOCK'!I24 -> 27000 | AM27: ='MASTER STOCK'!L24 -> 35100 | AN27: =AH27*AM27 -> 0 | AO27: =(AH27*AM27)-(AH27*AL27) -> 0
A28: ='MASTER STOCK'!F25 -> Lampu LED strip outdoor merah putih 10m +adaptor | B28: ='MASTER STOCK'!G25 -> 5 | AH28: =SUM(C28:AG28) -> 0 | AI28: =B28-SUM(C28:AG28) -> 5 | AJ28: =B28-AH28 -> 5 | AK28: =AJ28-AI28 -> 0 | AL28: ='MASTER STOCK'!I25 -> 30000 | AM28: ='MASTER STOCK'!L25 -> 40500 | AN28: =AH28*AM28 -> 0 | AO28: =(AH28*AM28)-(AH28*AL28) -> 0
A29: ='MASTER STOCK'!F26 -> Lampu tumbler 10m (rainbow) | B29: ='MASTER STOCK'!G26 -> 5 | AH29: =SUM(C29:AG29) -> 0 | AI29: =B29-SUM(C29:AG29) -> 5 | AJ29: =B29-AH29 -> 5 | AK29: =AJ29-AI29 -> 0 | AL29: ='MASTER STOCK'!I26 -> 11000 | AM29: ='MASTER STOCK'!L26 -> 14300 | AN29: =AH29*AM29 -> 0 | AO29: =(AH29*AM29)-(AH29*AL29) -> 0
A30: ='MASTER STOCK'!F27 -> WD Gerinda potong besi | B30: ='MASTER STOCK'!G27 -> 60 | Z30: 1 | AA30: 1 | AH30: =SUM(C30:AG30) -> 2 | AI30: =B30-SUM(C30:AG30) -> 58 | AJ30: =B30-AH30 -> 58 | AK30: =AJ30-AI30 -> 0 | AL30: ='MASTER STOCK'!I27 -> 2900 | AM30: ='MASTER STOCK'!L27 -> 5000 | AN30: =AH30*AM30 -> 10000 | AO30: =(AH30*AM30)-(AH30*AL30) -> 4200
A31: ='MASTER STOCK'!F28 -> Meteran karet 7,5m (merk HPP) | B31: ='MASTER STOCK'!G28 -> 3 | AH31: =SUM(C31:AG31) -> 0 | AI31: =B31-SUM(C31:AG31) -> 3 | AJ31: =B31-AH31 -> 3 | AK31: =AJ31-AI31 -> 0 | AL31: ='MASTER STOCK'!I28 -> 12800 | AM31: ='MASTER STOCK'!L28 -> 16640 | AN31: =AH31*AM31 -> 0 | AO31: =(AH31*AM31)-(AH31*AL31) -> 0
A32: ='MASTER STOCK'!F29 -> Meteran karet 5m (merk VPR) | B32: ='MASTER STOCK'!G29 -> 3 | AH32: =SUM(C32:AG32) -> 0 | AI32: =B32-SUM(C32:AG32) -> 3 | AJ32: =B32-AH32 -> 3 | AK32: =AJ32-AI32 -> 0 | AL32: ='MASTER STOCK'!I29 -> 7000 | AM32: ='MASTER STOCK'!L29 -> 9100 | AN32: =AH32*AM32 -> 0 | AO32: =(AH32*AM32)-(AH32*AL32) -> 0
A33: ='MASTER STOCK'!F30 -> Kuas cat 2 1/2" (merk MDN) | B33: ='MASTER STOCK'!G30 -> 5 | AH33: =SUM(C33:AG33) -> 0 | AI33: =B33-SUM(C33:AG33) -> 5 | AJ33: =B33-AH33 -> 5 | AK33: =AJ33-AI33 -> 0 | AL33: ='MASTER STOCK'!I30 -> 5300 | AM33: ='MASTER STOCK'!L30 -> 6890 | AN33: =AH33*AM33 -> 0 | AO33: =(AH33*AM33)-(AH33*AL33) -> 0
A34: ='MASTER STOCK'!F31 -> Kuas cat 2" (merk MDN) | B34: ='MASTER STOCK'!G31 -> 5 | AH34: =SUM(C34:AG34) -> 0 | AI34: =B34-SUM(C34:AG34) -> 5 | AJ34: =B34-AH34 -> 5 | AK34: =AJ34-AI34 -> 0 | AL34: ='MASTER STOCK'!I31 -> 4400 | AM34: ='MASTER STOCK'!L31 -> 5720 | AN34: =AH34*AM34 -> 0 | AO34: =(AH34*AM34)-(AH34*AL34) -> 0
A35: ='MASTER STOCK'!F32 -> Kuas cat 3" (merk MDN) | B35: ='MASTER STOCK'!G32 -> 5 | AH35: =SUM(C35:AG35) -> 0 | AI35: =B35-SUM(C35:AG35) -> 5 | AJ35: =B35-AH35 -> 5 | AK35: =AJ35-AI35 -> 0 | AL35: ='MASTER STOCK'!I32 -> 6300 | AM35: ='MASTER STOCK'!L32 -> 8190 | AN35: =AH35*AM35 -> 0 | AO35: =(AH35*AM35)-(AH35*AL35) -> 0
A36: ='MASTER STOCK'!F33 -> Kuas cat 1 1/2" (merk MDN) | B36: ='MASTER STOCK'!G33 -> 5 | AH36: =SUM(C36:AG36) -> 0 | AI36: =B36-SUM(C36:AG36) -> 5 | AJ36: =B36-AH36 -> 5 | AK36: =AJ36-AI36 -> 0 | AL36: ='MASTER STOCK'!I33 -> 3400 | AM36: ='MASTER STOCK'!L33 -> 4420 | AN36: =AH36*AM36 -> 0 | AO36: =(AH36*AM36)-(AH36*AL36) -> 0
A37: ='MASTER STOCK'!F34 -> Kuas cat 1" (merk MDN) | B37: ='MASTER STOCK'!G34 -> 5 | AH37: =SUM(C37:AG37) -> 0 | AI37: =B37-SUM(C37:AG37) -> 5 | AJ37: =B37-AH37 -> 5 | AK37: =AJ37-AI37 -> 0 | AL37: ='MASTER STOCK'!I34 -> 2300 | AM37: ='MASTER STOCK'!L34 -> 2990 | AN37: =AH37*AM37 -> 0 | AO37: =(AH37*AM37)-(AH37*AL37) -> 0
A38: ='MASTER STOCK'!F35 -> Kran PVC Tembok 3/4" | B38: ='MASTER STOCK'!G35 -> 24 | AH38: =SUM(C38:AG38) -> 0 | AI38: =B38-SUM(C38:AG38) -> 24 | AJ38: =B38-AH38 -> 24 | AK38: =AJ38-AI38 -> 0 | AL38: ='MASTER STOCK'!I35 -> 4200 | AM38: ='MASTER STOCK'!L35 -> 6000 | AN38: =AH38*AM38 -> 0 | AO38: =(AH38*AM38)-(AH38*AL38) -> 0
A39: ='MASTER STOCK'!F36 -> Kran PVC Tembok 1/2" | B39: ='MASTER STOCK'!G36 -> 24 | AH39: =SUM(C39:AG39) -> 0 | AI39: =B39-SUM(C39:AG39) -> 24 | AJ39: =B39-AH39 -> 24 | AK39: =AJ39-AI39 -> 0 | AL39: ='MASTER STOCK'!I36 -> 4200 | AM39: ='MASTER STOCK'!L36 -> 6000 | AN39: =AH39*AM39 -> 0 | AO39: =(AH39*AM39)-(AH39*AL39) -> 0
A40: ='MASTER STOCK'!F37 -> Lampu bohlam inlite 5w Putih | B40: ='MASTER STOCK'!G37 -> 7 | AH40: =SUM(C40:AG40) -> 0 | AI40: =B40-SUM(C40:AG40) -> 7 | AJ40: =B40-AH40 -> 7 | AK40: =AJ40-AI40 -> 0 | AL40: ='MASTER STOCK'!I37 -> 13000 | AM40: ='MASTER STOCK'!L37 -> 18200 | AN40: =AH40*AM40 -> 0 | AO40: =(AH40*AM40)-(AH40*AL40) -> 0
...

Sheet MASTER STOCK
A1: NO | B1: TANGGAL | C1: KODE BARANG | D1: KATEGORI | E1: NOMOR RESI | F1: NAMA BARANG | G1: QTY | H1: STOK AWAL | I1: HARGA BELI | J1: NOMINAL | K1: MARGIN | L1: HARGA JUAL | M1: HARGA ATAS | N1: HARGA BAWAH | O1: SUPPLIER | P1: STATUS | Q1: STATUS BARANG | R1: JATUH TEMPO | S1: QTY KULAK
A2: 1 | B2: 45847 | E2: 250709NWY3UCWW | F2: Fitting Gantung | G2: =H2+S2 -> 12 | H2: 12 | I2: 1400 | J2: =I2*G2 -> 16800 | K2: 0.3 | L2: =I2+((K2)*I2) -> 1820 | M2: 4000 | O2: Toko A8 (SHOPEE) | P2: LUNAS | Q2: TRUE | S2: 0
A3: 2 | B3: 45847 | E3: 250709NWY3UCWW | F3: Colokan T | G3: =H3+S3 -> 12 | H3: 12 | I3: 3000 | J3: =I3*G3 -> 36000 | K3: 0.3 | L3: =I3+((K3)*I3) -> 3900 | M3: 4000 | O3: Toko A8 (SHOPEE) | P3: LUNAS | Q3: TRUE | S3: 0
A4: 3 | B4: 45847 | E4: 250709NWY3UCWW | F4: Steker Bulat | G4: =H4+S4 -> 12 | H4: 12 | I4: 3000 | J4: =I4*G4 -> 36000 | K4: 0.3 | L4: 6000 | M4: 6000 | O4: Toko A8 (SHOPEE) | P4: LUNAS | Q4: TRUE | S4: 0
A5: 4 | B5: 45847 | E5: 250709NWY3UCWW | F5: Steker Gepeng | G5: =H5+S5 -> 12 | H5: 12 | I5: 1100 | J5: =I5*G5 -> 13200 | K5: 0.3 | L5: =I5+((K5)*I5) -> 1430 | M5: 3000 | O5: Toko A8 (SHOPEE) | P5: LUNAS | Q5: TRUE | S5: 0
A6: 5 | B6: 45847 | E6: 250709NWY3UCWW | F6: Saklar Gantung Putih jumbo | G6: =H6+S6 -> 12 | H6: 12 | I6: 2250 | J6: =I6*G6 -> 27000 | K6: 0.3 | L6: 4000 | M6: 4000 | O6: Toko A8 (SHOPEE) | P6: LUNAS | Q6: TRUE | S6: 0
A7: 6 | B7: 45847 | E7: 250709NWY3UCWW | F7: Saklar Gantung Hitam | G7: =H7+S7 -> 12 | H7: 12 | I7: 1850 | J7: =I7*G7 -> 22200 | K7: 0.3 | L7: 4000 | M7: 3500 | O7: Toko A8 (SHOPEE) | P7: LUNAS | Q7: TRUE | S7: 0
A8: 7 | B8: 45847 | C8: 8997777080323 | E8: 250709NWY3UCWX | F8: Isolasi Hitam National | G8: =H8+S8 -> 20 | H8: 20 | I8: 5150 | J8: =I8*G8 -> 103000 | K8: 0.55 | L8: =I8+((K8)*I8) -> 7982.5 | M8: 8000 | N8: 8000 | O8: ksam_uuwyn (SHOPEE) | P8: LUNAS | Q8: TRUE | S8: 0
A9: 8 | B9: 45847 | E9: 250709NXRSWD52 | F9: Lem PVC Isarplas 40gram | G9: =H9+S9 -> 24 | H9: 24 | I9: 6900 | J9: =I9*G9 -> 165600 | K9: 0.45 | L9: 9500 | M9: 9500 | O9: Arvella (SHOPEE) | P9: LUNAS | Q9: TRUE | S9: 0
A10: 9 | B10: 45847 | E10: 579559980040946979 | F10: Isolasi Kran air onda | G10: =H10+S10 -> 60 | H10: 60 | I10: 1150 | J10: =I10*G10 -> 69000 | K10: 0.3 | L10: =I10+((K10)*I10) -> 1495 | M10: 3000 | O10: Cakra Tools (TOKOPEDIA) | P10: LUNAS | Q10: TRUE | S10: 0
A11: 10 | B11: 45847 | E11: 579669984986359075 | F11: Tutup Pipa 3/4" | G11: =H11+S11 -> 50 | H11: 50 | I11: 850 | J11: =I11*G11 -> 42500 | K11: 0.5 | L11: =I11+((K11)*I11) -> 1275 | M11: 3000 | O11: PionTools Sby (TOKOPEDIA) | P11: LUNAS | Q11: TRUE | S11: 0
A12: 11 | B12: 45847 | E12: 579560031901418787 | F12: Fitting lampu gantung outdoor (10 m 5 fitting) | G12: =H12+S12 -> 1 | H12: 1 | I12: 38000 | J12: =I12*G12 -> 38000 | K12: 0.3 | L12: =I12+((K12)*I12) -> 49400 | M12: 48000 | O12: Msizg shop (TOKOPEDIA) | P12: LUNAS | Q12: TRUE | S12: 0
A13: 12 | B13: 45847 | E13: 579560282645497123 | F13: Obeng karet 4" plus | G13: =H13+S13 -> 5 | H13: 5 | I13: 5500 | J13: =I13*G13 -> 27500 | K13: 0.3 | L13: =I13+((K13)*I13) -> 7150 | M13: 11000 | O13: TripleWayElektrik (TOKOPEDIA) | P13: LUNAS | Q13: TRUE | S13: 0
A14: 13 | B14: 45847 | E14: 579560282645497123 | F14: Obeng karet 4" minus | G14: =H14+S14 -> 5 | H14: 5 | I14: 5500 | J14: =I14*G14 -> 27500 | K14: 0.3 | L14: =I14+((K14)*I14) -> 7150 | M14: 11000 | O14: TripleWayElektrik (TOKOPEDIA) | P14: LUNAS | Q14: TRUE | S14: 0
A15: 14 | B15: 45847 | E15: 579560282645497123 | F15: Obeng karet 6" plus | G15: =H15+S15 -> 5 | H15: 5 | I15: 7000 | J15: =I15*G15 -> 35000 | K15: 0.3 | L15: =I15+((K15)*I15) -> 9100 | M15: 14000 | O15: TripleWayElektrik (TOKOPEDIA) | P15: LUNAS | Q15: TRUE | S15: 0
A16: 15 | B16: 45847 | E16: 579560282645497123 | F16: Obeng karet 6" Minus | G16: =H16+S16 -> 5 | H16: 5 | I16: 7000 | J16: =I16*G16 -> 35000 | K16: 0.3 | L16: =I16+((K16)*I16) -> 9100 | M16: 14000 | O16: TripleWayElektrik (TOKOPEDIA) | P16: LUNAS | Q16: TRUE | S16: 0
A17: 16 | B17: 45847 | E17: 579560388730455331 | F17: Kabel Awg 24 Double 2x18 merah hitam | G17: =H17+S17 -> 2 | H17: 2 | I17: 106500 | J17: =I17*G17 -> 213000 | K17: 0.7 | L17: =I17+((K17)*I17) -> 181050 | M17: 3500 | O17: manse.strore (TOKOPEDIA) | P17: LUNAS | Q17: TRUE | S17: 0
A18: 17 | B18: 45847 | E18: 579560388730127651 | F18: Kabel bintik serabut tembaga motor mobil 20mx0.5mm/0,85mm merah 0,5mm | G18: =H18+S18 -> 2 | H18: 2 | I18: 33700 | J18: =I18*G18 -> 67400 | K18: 0.7 | L18: =I18+((K18)*I18) -> 57290 | M18: 3000 | O18: GLOBAL LED MOTORINDO (TOKOPEDIA) | P18: LUNAS | Q18: TRUE | S18: 0
A19: 18 | B19: 45847 | E19: 579560388730127651 | F19: Kabel bintik serabut tembaga motor mobil 20mx0.5mm/0,85mm hitam 0,5mm | G19: =H19+S19 -> 2 | H19: 2 | I19: 33700 | J19: =I19*G19 -> 67400 | K19: 0.7 | L19: =I19+((K19)*I19) -> 57290 | M19: 3000 | O19: GLOBAL LED MOTORINDO (TOKOPEDIA) | P19: LUNAS | Q19: TRUE | S19: 0
A20: 19 | B20: 45847 | F20: Mata Gerinda keramik 4 inch kering | G20: =H20+S20 -> 5 | H20: 5 | I20: 12000 | J20: =I20*G20 -> 60000 | K20: 0.5 | L20: =I20+((K20)*I20) -> 18000 | M20: 18000 | P20: LUNAS | Q20: TRUE | S20: 0
A21: 20 | B21: 45847 | F21: Kabel tunggal serabut 0.8mmx25m biru 25m | G21: =H21+S21 -> 1 | H21: 1 | I21: 17500 | J21: =I21*G21 -> 17500 | K21: 0.7 | L21: =I21+((K21)*I21) -> 29750 | M21: 2000 | O21: Bintang Terang Listrik (TOKOPEDIA) | P21: LUNAS | Q21: TRUE | S21: 0
A22: 21 | B22: 45847 | F22: Kabel tunggal serabut 0.8mmx25m Hitam 25m | G22: =H22+S22 -> 1 | H22: 1 | I22: 17500 | J22: =I22*G22 -> 17500 | K22: 0.7 | L22: =I22+((K22)*I22) -> 29750 | M22: 2000 | O22: Bintang Terang Listrik (TOKOPEDIA) | P22: LUNAS | Q22: TRUE | S22: 0
A23: 22 | B23: 45847 | F23: Lampu Hias LED strip USB 10m+adaptor | G23: =H23+S23 -> 2 | H23: 2 | I23: 50000 | J23: =I23*G23 -> 100000 | K23: 0.3 | L23: =I23+((K23)*I23) -> 65000 | M23: 65000 | P23: LUNAS | Q23: TRUE | S23: 0
A24: 23 | B24: 45847 | F24: Lampu LED strip outdoor rainbow 10m +adaptor | G24: =H24+S24 -> 5 | H24: 5 | I24: 27000 | J24: =I24*G24 -> 135000 | K24: 0.3 | L24: =I24+((K24)*I24) -> 35100 | M24: 45000 | P24: LUNAS | Q24: TRUE | S24: 0
A25: 24 | B25: 45847 | F25: Lampu LED strip outdoor merah putih 10m +adaptor | G25: =H25+S25 -> 5 | H25: 5 | I25: 30000 | J25: =I25*G25 -> 150000 | K25: 0.35 | L25: =I25+((K25)*I25) -> 40500 | M25: 40000 | P25: LUNAS | Q25: TRUE | S25: 0
A26: 25 | B26: 45847 | F26: Lampu tumbler 10m (rainbow) | G26: =H26+S26 -> 5 | H26: 5 | I26: 11000 | J26: =I26*G26 -> 55000 | K26: 0.3 | L26: =I26+((K26)*I26) -> 14300 | M26: 15000 | P26: LUNAS | Q26: TRUE | S26: 0
A27: 26 | B27: 45847 | E27: 250709NYQK3BEY | F27: WD Gerinda potong besi | G27: =H27+S27 -> 60 | H27: 20 | I27: 2900 | J27: =I27*G27 -> 174000 | K27: 0.5 | L27: 5000 | M27: 5000 | O27: Artha Tirta Bangunan (SHOPEE) | P27: LUNAS | Q27: TRUE | S27: 40
A28: 27 | B28: 45847 | E28: 250709NYQK3BEY | F28: Meteran karet 7,5m (merk HPP) | G28: =H28+S28 -> 3 | H28: 3 | I28: 12800 | J28: =I28*G28 -> 38400 | K28: 0.3 | L28: =I28+((K28)*I28) -> 16640 | M28: 17000 | O28: Artha Tirta Bangunan (SHOPEE) | P28: LUNAS | Q28: TRUE | S28: 0
A29: 28 | B29: 45847 | E29: 250709NYQK3BEY | F29: Meteran karet 5m (merk VPR) | G29: =H29+S29 -> 3 | H29: 3 | I29: 7000 | J29: =I29*G29 -> 21000 | K29: 0.3 | L29: =I29+((K29)*I29) -> 9100 | M29: 11000 | O29: Artha Tirta Bangunan (SHOPEE) | P29: LUNAS | Q29: TRUE | S29: 0
A30: 29 | B30: 45847 | E30: 250709NYQK3BEY | F30: Kuas cat 2 1/2" (merk MDN) | G30: =H30+S30 -> 5 | H30: 5 | I30: 5300 | J30: =I30*G30 -> 26500 | K30: 0.3 | L30: =I30+((K30)*I30) -> 6890 | M30: 7000 | O30: Artha Tirta Bangunan (SHOPEE) | P30: LUNAS | Q30: TRUE | S30: 0
A31: 30 | B31: 45847 | E31: 250709NYQK3BEY | F31: Kuas cat 2" (merk MDN) | G31: =H31+S31 -> 5 | H31: 5 | I31: 4400 | J31: =I31*G31 -> 22000 | K31: 0.3 | L31: =I31+((K31)*I31) -> 5720 | M31: 6000 | O31: Artha Tirta Bangunan (SHOPEE) | P31: LUNAS | Q31: TRUE | S31: 0
A32: 31 | B32: 45847 | E32: 250709NYQK3BEY | F32: Kuas cat 3" (merk MDN) | G32: =H32+S32 -> 5 | H32: 5 | I32: 6300 | J32: =I32*G32 -> 31500 | K32: 0.3 | L32: =I32+((K32)*I32) -> 8190 | M32: 8500 | O32: Artha Tirta Bangunan (SHOPEE) | P32: LUNAS | Q32: TRUE | S32: 0
A33: 32 | B33: 45847 | E33: 250709NYQK3BEY | F33: Kuas cat 1 1/2" (merk MDN) | G33: =H33+S33 -> 5 | H33: 5 | I33: 3400 | J33: =I33*G33 -> 17000 | K33: 0.3 | L33: =I33+((K33)*I33) -> 4420 | M33: 5000 | O33: Artha Tirta Bangunan (SHOPEE) | P33: LUNAS | Q33: TRUE | S33: 0
A34: 33 | B34: 45847 | E34: 250709NYQK3BEY | F34: Kuas cat 1" (merk MDN) | G34: =H34+S34 -> 5 | H34: 5 | I34: 2300 | J34: =I34*G34 -> 11500 | K34: 0.3 | L34: =I34+((K34)*I34) -> 2990 | M34: 4000 | O34: Artha Tirta Bangunan (SHOPEE) | P34: LUNAS | Q34: TRUE | S34: 0
A35: 34 | B35: 45847 | E35: 250709P0689QTR | F35: Kran PVC Tembok 3/4" | G35: =H35+S35 -> 24 | H35: 12 | I35: 4200 | J35: =I35*G35 -> 100800 | K35: 0.5 | L35: 6000 | M35: 6000 | O35: LARIS.CO* | P35: LUNAS | Q35: TRUE | S35: 12
A36: 35 | B36: 45847 | E36: 250709P0689QTR | F36: Kran PVC Tembok 1/2" | G36: =H36+S36 -> 24 | H36: 12 | I36: 4200 | J36: =I36*G36 -> 100800 | K36: 0.5 | L36: 6000 | M36: 6000 | O36: LARIS.CO* | P36: LUNAS | Q36: TRUE | S36: 12
A37: 36 | B37: 45847 | E37: 579563506087200035 | F37: Lampu bohlam inlite 5w Putih | G37: =H37+S37 -> 7 | H37: 7 | I37: 13000 | J37: =I37*G37 -> 91000 | K37: 0.4 | L37: =I37+((K37)*I37) -> 18200 | M37: 18000 | O37: GLOBAL PERKASA INDAH (TOKOPEDIA) | P37: LUNAS | Q37: TRUE | S37: 0
A38: 37 | B38: 45847 | E38: 579563506087200035 | F38: Lampu bohlam inlite 7w Putih | G38: =H38+S38 -> 2 | H38: 2 | I38: 16200 | J38: =I38*G38 -> 32400 | K38: 0.4 | L38: =I38+((K38)*I38) -> 22680 | M38: 22000 | O38: GLOBAL PERKASA INDAH (TOKOPEDIA) | P38: LUNAS | Q38: TRUE | S38: 0
A39: 38 | B39: 45847 | E39: 579563506087200035 | F39: Lampu bohlam inlite 15w Putih | G39: =H39+S39 -> 4 | H39: 4 | I39: 28000 | J39: =I39*G39 -> 112000 | K39: 0.4 | L39: =I39+((K39)*I39) -> 39200 | M39: 37000 | O39: GLOBAL PERKASA INDAH (TOKOPEDIA) | P39: LUNAS | Q39: TRUE | S39: 0
A40: 39 | B40: 45847 | E40: 579563506087200035 | F40: Lampu bohlam inlite 12w Putih | G40: =H40+S40 -> 6 | H40: 6 | I40: 25000 | J40: =I40*G40 -> 150000 | K40: 0.4 | L40: 30000 | M40: 30000 | O40: GLOBAL PERKASA INDAH (TOKOPEDIA) | P40: LUNAS | Q40: TRUE | S40: 0
...

Sheet JULI 25
A1: LAPORAN PENJUALAN BULANAN | AQ1: 45839
A2: NAMA BARANG | B2: STOK AWAL | C2: =UPPER("HARI / BULAN : " & TEXT(AQ1, "MMMM YYYY")) -> HARI / BULAN : JULI 2025
C3: =TEXT(C4,"dddd") -> Selasa | D3: =TEXT(D4,"dddd") -> Rabu | E3: =TEXT(E4,"dddd") -> Kamis | F3: =TEXT(F4,"dddd") -> Jumat | G3: =TEXT(G4,"dddd") -> Sabtu | H3: =TEXT(H4,"dddd") -> Minggu | I3: =TEXT(I4,"dddd") -> Senin | J3: =TEXT(J4,"dddd") -> Selasa | ... AG3: =TEXT(AG4,"dddd") -> Kamis | AH3: TOTAL | AI3: STOCK | AJ3: SYSTEM | AK3: KET/SELISIH | AL3: HARGA BELI | AM3: HARGA JUAL | AN3: OMSET | AO3: PROFIT | AP3: TOTAL MODAL
C4: =AQ1 -> 45839 | D4: =IF(AND(MONTH(C4+1) = MONTH(C4), C4<>""),C4 + 1, "") -> 45840 | E4: =IF(AND(MONTH(D4+1) = MONTH(D4), D4<>""),D4 + 1, "") -> 45841 | F4: =IF(AND(MONTH(E4+1) = MONTH(E4), E4<>""),E4 + 1, "") -> 45842 | G4: =IF(AND(MONTH(F4+1) = MONTH(F4), F4<>""),F4 + 1, "") -> 45843 | H4: =IF(AND(MONTH(G4+1) = MONTH(G4), G4<>""),G4 + 1, "") -> 45844 | I4: =IF(AND(MONTH(H4+1) = MONTH(H4), H4<>""),H4 + 1, "") -> 45845 | J4: =IF(AND(MONTH(I4+1) = MONTH(I4), I4<>""),I4 + 1, "") -> 45846 | K4: =IF(AND(MONTH(J4+1) = MONTH(J4), J4<>""),J4 + 1, "") -> 45847 | ... AG4: =IF(AND(MONTH(AF4+1) = MONTH(AF4), AF4<>""),AF4 + 1, "") -> 45869
A5: ='MASTER STOCK'!F2 -> Fitting Gantung | B5: ='MASTER STOCK'!G2 -> 12 | AH5: =SUM(C5:AG5) -> 0 | AI5: =B5-SUM(C5:AG5) -> 12 | AJ5: =B5-AH5 -> 12 | AK5: =AJ5-AI5 -> 0 | AL5: ='MASTER STOCK'!I2 -> 1400 | AM5: ='MASTER STOCK'!L2 -> 1820 | AN5: =AH5*AM5 -> 0 | AO5: =AN5-(AH5*AL5) -> 0 | AP5: =AH5*AL5 -> 0
A6: ='MASTER STOCK'!F3 -> Colokan T | B6: ='MASTER STOCK'!G3 -> 12 | AH6: =SUM(C6:AG6) -> 0 | AI6: =B6-SUM(C6:AG6) -> 12 | AJ6: =B6-AH6 -> 12 | AK6: =AJ6-AI6 -> 0 | AL6: ='MASTER STOCK'!I3 -> 3000 | AM6: ='MASTER STOCK'!L3 -> 3900 | AN6: =AH6*AM6 -> 0 | AO6: =AN6-(AH6*AL6) -> 0 | AP6: =AH6*AL6 -> 0
A7: ='MASTER STOCK'!F4 -> Steker Bulat | B7: ='MASTER STOCK'!G4 -> 12 | AH7: =SUM(C7:AG7) -> 0 | AI7: =B7-SUM(C7:AG7) -> 12 | AJ7: =B7-AH7 -> 12 | AK7: =AJ7-AI7 -> 0 | AL7: ='MASTER STOCK'!I4 -> 3000 | AM7: ='MASTER STOCK'!L4 -> 6000 | AN7: =AH7*AM7 -> 0 | AO7: =AN7-(AH7*AL7) -> 0 | AP7: =AH7*AL7 -> 0
A8: ='MASTER STOCK'!F5 -> Steker Gepeng | B8: ='MASTER STOCK'!G5 -> 12 | AH8: =SUM(C8:AG8) -> 0 | AI8: =B8-SUM(C8:AG8) -> 12 | AJ8: =B8-AH8 -> 12 | AK8: =AJ8-AI8 -> 0 | AL8: ='MASTER STOCK'!I5 -> 1100 | AM8: ='MASTER STOCK'!L5 -> 1430 | AN8: =AH8*AM8 -> 0 | AO8: =AN8-(AH8*AL8) -> 0 | AP8: =AH8*AL8 -> 0
A9: ='MASTER STOCK'!F6 -> Saklar Gantung Putih jumbo | B9: ='MASTER STOCK'!G6 -> 12 | AH9: =SUM(C9:AG9) -> 0 | AI9: =B9-SUM(C9:AG9) -> 12 | AJ9: =B9-AH9 -> 12 | AK9: =AJ9-AI9 -> 0 | AL9: ='MASTER STOCK'!I6 -> 2250 | AM9: ='MASTER STOCK'!L6 -> 4000 | AN9: =AH9*AM9 -> 0 | AO9: =AN9-(AH9*AL9) -> 0 | AP9: =AH9*AL9 -> 0
A10: ='MASTER STOCK'!F7 -> Saklar Gantung Hitam | B10: ='MASTER STOCK'!G7 -> 12 | AH10: =SUM(C10:AG10) -> 0 | AI10: =B10-SUM(C10:AG10) -> 12 | AJ10: =B10-AH10 -> 12 | AK10: =AJ10-AI10 -> 0 | AL10: ='MASTER STOCK'!I7 -> 1850 | AM10: ='MASTER STOCK'!L7 -> 4000 | AN10: =AH10*AM10 -> 0 | AO10: =AN10-(AH10*AL10) -> 0 | AP10: =AH10*AL10 -> 0
A11: ='MASTER STOCK'!F8 -> Isolasi Hitam National | B11: ='MASTER STOCK'!G8 -> 20 | AH11: =SUM(C11:AG11) -> 0 | AI11: =B11-SUM(C11:AG11) -> 20 | AJ11: =B11-AH11 -> 20 | AK11: =AJ11-AI11 -> 0 | AL11: ='MASTER STOCK'!I8 -> 5150 | AM11: ='MASTER STOCK'!L8 -> 7982.5 | AN11: =AH11*AM11 -> 0 | AO11: =AN11-(AH11*AL11) -> 0 | AP11: =AH11*AL11 -> 0
A12: ='MASTER STOCK'!F9 -> Lem PVC Isarplas 40gram | B12: ='MASTER STOCK'!G9 -> 24 | AH12: =SUM(C12:AG12) -> 0 | AI12: =B12-SUM(C12:AG12) -> 24 | AJ12: =B12-AH12 -> 24 | AK12: =AJ12-AI12 -> 0 | AL12: ='MASTER STOCK'!I9 -> 6900 | AM12: ='MASTER STOCK'!L9 -> 9500 | AN12: =AH12*AM12 -> 0 | AO12: =AN12-(AH12*AL12) -> 0 | AP12: =AH12*AL12 -> 0
A13: ='MASTER STOCK'!F10 -> Isolasi Kran air onda | B13: ='MASTER STOCK'!G10 -> 60 | AH13: =SUM(C13:AG13) -> 0 | AI13: =B13-SUM(C13:AG13) -> 60 | AJ13: =B13-AH13 -> 60 | AK13: =AJ13-AI13 -> 0 | AL13: ='MASTER STOCK'!I10 -> 1150 | AM13: ='MASTER STOCK'!L10 -> 1495 | AN13: =AH13*AM13 -> 0 | AO13: =AN13-(AH13*AL13) -> 0 | AP13: =AH13*AL13 -> 0
A14: ='MASTER STOCK'!F11 -> Tutup Pipa 3/4" | B14: ='MASTER STOCK'!G11 -> 50 | AH14: =SUM(C14:AG14) -> 0 | AI14: =B14-SUM(C14:AG14) -> 50 | AJ14: =B14-AH14 -> 50 | AK14: =AJ14-AI14 -> 0 | AL14: ='MASTER STOCK'!I11 -> 850 | AM14: ='MASTER STOCK'!L11 -> 1275 | AN14: =AH14*AM14 -> 0 | AO14: =AN14-(AH14*AL14) -> 0 | AP14: =AH14*AL14 -> 0
A15: ='MASTER STOCK'!F12 -> Fitting lampu gantung outdoor (10 m 5 fitting) | B15: ='MASTER STOCK'!G12 -> 1 | AH15: =SUM(C15:AG15) -> 0 | AI15: =B15-SUM(C15:AG15) -> 1 | AJ15: =B15-AH15 -> 1 | AK15: =AJ15-AI15 -> 0 | AL15: ='MASTER STOCK'!I12 -> 38000 | AM15: ='MASTER STOCK'!L12 -> 49400 | AN15: =AH15*AM15 -> 0 | AO15: =AN15-(AH15*AL15) -> 0 | AP15: =AH15*AL15 -> 0
A16: ='MASTER STOCK'!F13 -> Obeng karet 4" plus | B16: ='MASTER STOCK'!G13 -> 5 | AH16: =SUM(C16:AG16) -> 0 | AI16: =B16-SUM(C16:AG16) -> 5 | AJ16: =B16-AH16 -> 5 | AK16: =AJ16-AI16 -> 0 | AL16: ='MASTER STOCK'!I13 -> 5500 | AM16: ='MASTER STOCK'!L13 -> 7150 | AN16: =AH16*AM16 -> 0 | AO16: =AN16-(AH16*AL16) -> 0 | AP16: =AH16*AL16 -> 0
A17: ='MASTER STOCK'!F14 -> Obeng karet 4" minus | B17: ='MASTER STOCK'!G14 -> 5 | S17: 1 | AH17: =SUM(C17:AG17) -> 1 | AI17: =B17-SUM(C17:AG17) -> 4 | AJ17: =B17-AH17 -> 4 | AK17: =AJ17-AI17 -> 0 | AL17: ='MASTER STOCK'!I14 -> 5500 | AM17: ='MASTER STOCK'!L14 -> 7150 | AN17: =AH17*AM17 -> 7150 | AO17: =AN17-(AH17*AL17) -> 1650 | AP17: =AH17*AL17 -> 5500
A18: ='MASTER STOCK'!F15 -> Obeng karet 6" plus | B18: ='MASTER STOCK'!G15 -> 5 | AH18: =SUM(C18:AG18) -> 0 | AI18: =B18-SUM(C18:AG18) -> 5 | AJ18: =B18-AH18 -> 5 | AK18: =AJ18-AI18 -> 0 | AL18: ='MASTER STOCK'!I15 -> 7000 | AM18: ='MASTER STOCK'!L15 -> 9100 | AN18: =AH18*AM18 -> 0 | AO18: =AN18-(AH18*AL18) -> 0 | AP18: =AH18*AL18 -> 0
A19: ='MASTER STOCK'!F16 -> Obeng karet 6" Minus | B19: ='MASTER STOCK'!G16 -> 5 | AH19: =SUM(C19:AG19) -> 0 | AI19: =B19-SUM(C19:AG19) -> 5 | AJ19: =B19-AH19 -> 5 | AK19: =AJ19-AI19 -> 0 | AL19: ='MASTER STOCK'!I16 -> 7000 | AM19: ='MASTER STOCK'!L16 -> 9100 | AN19: =AH19*AM19 -> 0 | AO19: =AN19-(AH19*AL19) -> 0 | AP19: =AH19*AL19 -> 0
A20: ='MASTER STOCK'!F17 -> Kabel Awg 24 Double 2x18 merah hitam | B20: ='MASTER STOCK'!G17 -> 2 | AH20: =SUM(C20:AG20) -> 0 | AI20: =B20-SUM(C20:AG20) -> 2 | AJ20: =B20-AH20 -> 2 | AK20: =AJ20-AI20 -> 0 | AL20: ='MASTER STOCK'!I17 -> 106500 | AM20: ='MASTER STOCK'!L17 -> 181050 | AN20: =AH20*AM20 -> 0 | AO20: =AN20-(AH20*AL20) -> 0 | AP20: =AH20*AL20 -> 0
A21: ='MASTER STOCK'!F18 -> Kabel bintik serabut tembaga motor mobil 20mx0.5mm/0,85mm merah 0,5mm | B21: ='MASTER STOCK'!G18 -> 2 | AH21: =SUM(C21:AG21) -> 0 | AI21: =B21-SUM(C21:AG21) -> 2 | AJ21: =B21-AH21 -> 2 | AK21: =AJ21-AI21 -> 0 | AL21: ='MASTER STOCK'!I18 -> 33700 | AM21: ='MASTER STOCK'!L18 -> 57290 | AN21: =AH21*AM21 -> 0 | AO21: =AN21-(AH21*AL21) -> 0 | AP21: =AH21*AL21 -> 0
A22: ='MASTER STOCK'!F19 -> Kabel bintik serabut tembaga motor mobil 20mx0.5mm/0,85mm hitam 0,5mm | B22: ='MASTER STOCK'!G19 -> 2 | AH22: =SUM(C22:AG22) -> 0 | AI22: =B22-SUM(C22:AG22) -> 2 | AJ22: =B22-AH22 -> 2 | AK22: =AJ22-AI22 -> 0 | AL22: ='MASTER STOCK'!I19 -> 33700 | AM22: ='MASTER STOCK'!L19 -> 57290 | AN22: =AH22*AM22 -> 0 | AO22: =AN22-(AH22*AL22) -> 0 | AP22: =AH22*AL22 -> 0
A23: ='MASTER STOCK'!F20 -> Mata Gerinda keramik 4 inch kering | B23: ='MASTER STOCK'!G20 -> 5 | AH23: =SUM(C23:AG23) -> 0 | AI23: =B23-SUM(C23:AG23) -> 5 | AJ23: =B23-AH23 -> 5 | AK23: =AJ23-AI23 -> 0 | AL23: ='MASTER STOCK'!I20 -> 12000 | AM23: ='MASTER STOCK'!L20 -> 18000 | AN23: =AH23*AM23 -> 0 | AO23: =AN23-(AH23*AL23) -> 0 | AP23: =AH23*AL23 -> 0
A24: ='MASTER STOCK'!F21 -> Kabel tunggal serabut 0.8mmx25m biru 25m | B24: ='MASTER STOCK'!G21 -> 1 | AH24: =SUM(C24:AG24) -> 0 | AI24: =B24-SUM(C24:AG24) -> 1 | AJ24: =B24-AH24 -> 1 | AK24: =AJ24-AI24 -> 0 | AL24: ='MASTER STOCK'!I21 -> 17500 | AM24: ='MASTER STOCK'!L21 -> 29750 | AN24: =AH24*AM24 -> 0 | AO24: =AN24-(AH24*AL24) -> 0 | AP24: =AH24*AL24 -> 0
A25: ='MASTER STOCK'!F22 -> Kabel tunggal serabut 0.8mmx25m Hitam 25m | B25: ='MASTER STOCK'!G22 -> 1 | AH25: =SUM(C25:AG25) -> 0 | AI25: =B25-SUM(C25:AG25) -> 1 | AJ25: =B25-AH25 -> 1 | AK25: =AJ25-AI25 -> 0 | AL25: ='MASTER STOCK'!I22 -> 17500 | AM25: ='MASTER STOCK'!L22 -> 29750 | AN25: =AH25*AM25 -> 0 | AO25: =AN25-(AH25*AL25) -> 0 | AP25: =AH25*AL25 -> 0
A26: ='MASTER STOCK'!F23 -> Lampu Hias LED strip USB 10m+adaptor | B26: ='MASTER STOCK'!G23 -> 2 | AH26: =SUM(C26:AG26) -> 0 | AI26: =B26-SUM(C26:AG26) -> 2 | AJ26: =B26-AH26 -> 2 | AK26: =AJ26-AI26 -> 0 | AL26: ='MASTER STOCK'!I23 -> 50000 | AM26: ='MASTER STOCK'!L23 -> 65000 | AN26: =AH26*AM26 -> 0 | AO26: =AN26-(AH26*AL26) -> 0 | AP26: =AH26*AL26 -> 0
A27: ='MASTER STOCK'!F24 -> Lampu LED strip outdoor rainbow 10m +adaptor | B27: ='MASTER STOCK'!G24 -> 5 | AH27: =SUM(C27:AG27) -> 0 | AI27: =B27-SUM(C27:AG27) -> 5 | AJ27: =B27-AH27 -> 5 | AK27: =AJ27-AI27 -> 0 | AL27: ='MASTER STOCK'!I24 -> 27000 | AM27: ='MASTER STOCK'!L24 -> 35100 | AN27: =AH27*AM27 -> 0 | AO27: =AN27-(AH27*AL27) -> 0 | AP27: =AH27*AL27 -> 0
A28: ='MASTER STOCK'!F25 -> Lampu LED strip outdoor merah putih 10m +adaptor | B28: ='MASTER STOCK'!G25 -> 5 | AH28: =SUM(C28:AG28) -> 0 | AI28: =B28-SUM(C28:AG28) -> 5 | AJ28: =B28-AH28 -> 5 | AK28: =AJ28-AI28 -> 0 | AL28: ='MASTER STOCK'!I25 -> 30000 | AM28: ='MASTER STOCK'!L25 -> 40500 | AN28: =AH28*AM28 -> 0 | AO28: =AN28-(AH28*AL28) -> 0 | AP28: =AH28*AL28 -> 0
A29: ='MASTER STOCK'!F26 -> Lampu tumbler 10m (rainbow) | B29: ='MASTER STOCK'!G26 -> 5 | AH29: =SUM(C29:AG29) -> 0 | AI29: =B29-SUM(C29:AG29) -> 5 | AJ29: =B29-AH29 -> 5 | AK29: =AJ29-AI29 -> 0 | AL29: ='MASTER STOCK'!I26 -> 11000 | AM29: ='MASTER STOCK'!L26 -> 14300 | AN29: =AH29*AM29 -> 0 | AO29: =AN29-(AH29*AL29) -> 0 | AP29: =AH29*AL29 -> 0
A30: ='MASTER STOCK'!F27 -> WD Gerinda potong besi | B30: ='MASTER STOCK'!G27 -> 60 | Z30: 1 | AA30: 1 | AH30: =SUM(C30:AG30) -> 2 | AI30: =B30-SUM(C30:AG30) -> 58 | AJ30: =B30-AH30 -> 58 | AK30: =AJ30-AI30 -> 0 | AL30: ='MASTER STOCK'!I27 -> 2900 | AM30: ='MASTER STOCK'!L27 -> 5000 | AN30: =AH30*AM30 -> 10000 | AO30: =AN30-(AH30*AL30) -> 4200 | AP30: =AH30*AL30 -> 5800
A31: ='MASTER STOCK'!F28 -> Meteran karet 7,5m (merk HPP) | B31: ='MASTER STOCK'!G28 -> 3 | AH31: =SUM(C31:AG31) -> 0 | AI31: =B31-SUM(C31:AG31) -> 3 | AJ31: =B31-AH31 -> 3 | AK31: =AJ31-AI31 -> 0 | AL31: ='MASTER STOCK'!I28 -> 12800 | AM31: ='MASTER STOCK'!L28 -> 16640 | AN31: =AH31*AM31 -> 0 | AO31: =AN31-(AH31*AL31) -> 0 | AP31: =AH31*AL31 -> 0
A32: ='MASTER STOCK'!F29 -> Meteran karet 5m (merk VPR) | B32: ='MASTER STOCK'!G29 -> 3 | AH32: =SUM(C32:AG32) -> 0 | AI32: =B32-SUM(C32:AG32) -> 3 | AJ32: =B32-AH32 -> 3 | AK32: =AJ32-AI32 -> 0 | AL32: ='MASTER STOCK'!I29 -> 7000 | AM32: ='MASTER STOCK'!L29 -> 9100 | AN32: =AH32*AM32 -> 0 | AO32: =AN32-(AH32*AL32) -> 0 | AP32: =AH32*AL32 -> 0
A33: ='MASTER STOCK'!F30 -> Kuas cat 2 1/2" (merk MDN) | B33: ='MASTER STOCK'!G30 -> 5 | AH33: =SUM(C33:AG33) -> 0 | AI33: =B33-SUM(C33:AG33) -> 5 | AJ33: =B33-AH33 -> 5 | AK33: =AJ33-AI33 -> 0 | AL33: ='MASTER STOCK'!I30 -> 5300 | AM33: ='MASTER STOCK'!L30 -> 6890 | AN33: =AH33*AM33 -> 0 | AO33: =AN33-(AH33*AL33) -> 0 | AP33: =AH33*AL33 -> 0
A34: ='MASTER STOCK'!F31 -> Kuas cat 2" (merk MDN) | B34: ='MASTER STOCK'!G31 -> 5 | AH34: =SUM(C34:AG34) -> 0 | AI34: =B34-SUM(C34:AG34) -> 5 | AJ34: =B34-AH34 -> 5 | AK34: =AJ34-AI34 -> 0 | AL34: ='MASTER STOCK'!I31 -> 4400 | AM34: ='MASTER STOCK'!L31 -> 5720 | AN34: =AH34*AM34 -> 0 | AO34: =AN34-(AH34*AL34) -> 0 | AP34: =AH34*AL34 -> 0
A35: ='MASTER STOCK'!F32 -> Kuas cat 3" (merk MDN) | B35: ='MASTER STOCK'!G32 -> 5 | AH35: =SUM(C35:AG35) -> 0 | AI35: =B35-SUM(C35:AG35) -> 5 | AJ35: =B35-AH35 -> 5 | AK35: =AJ35-AI35 -> 0 | AL35: ='MASTER STOCK'!I32 -> 6300 | AM35: ='MASTER STOCK'!L32 -> 8190 | AN35: =AH35*AM35 -> 0 | AO35: =AN35-(AH35*AL35) -> 0 | AP35: =AH35*AL35 -> 0
A36: ='MASTER STOCK'!F33 -> Kuas cat 1 1/2" (merk MDN) | B36: ='MASTER STOCK'!G33 -> 5 | AH36: =SUM(C36:AG36) -> 0 | AI36: =B36-SUM(C36:AG36) -> 5 | AJ36: =B36-AH36 -> 5 | AK36: =AJ36-AI36 -> 0 | AL36: ='MASTER STOCK'!I33 -> 3400 | AM36: ='MASTER STOCK'!L33 -> 4420 | AN36: =AH36*AM36 -> 0 | AO36: =AN36-(AH36*AL36) -> 0 | AP36: =AH36*AL36 -> 0
A37: ='MASTER STOCK'!F34 -> Kuas cat 1" (merk MDN) | B37: ='MASTER STOCK'!G34 -> 5 | AH37: =SUM(C37:AG37) -> 0 | AI37: =B37-SUM(C37:AG37) -> 5 | AJ37: =B37-AH37 -> 5 | AK37: =AJ37-AI37 -> 0 | AL37: ='MASTER STOCK'!I34 -> 2300 | AM37: ='MASTER STOCK'!L34 -> 2990 | AN37: =AH37*AM37 -> 0 | AO37: =AN37-(AH37*AL37) -> 0 | AP37: =AH37*AL37 -> 0
A38: ='MASTER STOCK'!F35 -> Kran PVC Tembok 3/4" | B38: ='MASTER STOCK'!G35 -> 24 | AH38: =SUM(C38:AG38) -> 0 | AI38: =B38-SUM(C38:AG38) -> 24 | AJ38: =B38-AH38 -> 24 | AK38: =AJ38-AI38 -> 0 | AL38: ='MASTER STOCK'!I35 -> 4200 | AM38: ='MASTER STOCK'!L35 -> 6000 | AN38: =AH38*AM38 -> 0 | AO38: =AN38-(AH38*AL38) -> 0 | AP38: =AH38*AL38 -> 0
A39: ='MASTER STOCK'!F36 -> Kran PVC Tembok 1/2" | B39: ='MASTER STOCK'!G36 -> 24 | AH39: =SUM(C39:AG39) -> 0 | AI39: =B39-SUM(C39:AG39) -> 24 | AJ39: =B39-AH39 -> 24 | AK39: =AJ39-AI39 -> 0 | AL39: ='MASTER STOCK'!I36 -> 4200 | AM39: ='MASTER STOCK'!L36 -> 6000 | AN39: =AH39*AM39 -> 0 | AO39: =AN39-(AH39*AL39) -> 0 | AP39: =AH39*AL39 -> 0
A40: ='MASTER STOCK'!F37 -> Lampu bohlam inlite 5w Putih | B40: ='MASTER STOCK'!G37 -> 7 | AH40: =SUM(C40:AG40) -> 0 | AI40: =B40-SUM(C40:AG40) -> 7 | AJ40: =B40-AH40 -> 7 | AK40: =AJ40-AI40 -> 0 | AL40: ='MASTER STOCK'!I37 -> 13000 | AM40: ='MASTER STOCK'!L37 -> 18200 | AN40: =AH40*AM40 -> 0 | AO40: =AN40-(AH40*AL40) -> 0 | AP40: =AH40*AL40 -> 0
...

Sheet AGS 25
A1: LAPORAN PENJUALAN BULANAN | AQ1: 45870
A2: NAMA BARANG | B2: STOK AWAL | C2: =UPPER("HARI / BULAN : " & TEXT(AQ1, "MMMM YYYY")) -> HARI / BULAN : AGUSTUS 2025
C3: =TEXT(C4,"dddd") -> Jumat | D3: =TEXT(D4,"dddd") -> Sabtu | E3: =TEXT(E4,"dddd") -> Minggu | F3: =TEXT(F4,"dddd") -> Senin | G3: =TEXT(G4,"dddd") -> Selasa | H3: =TEXT(H4,"dddd") -> Rabu | I3: =TEXT(I4,"dddd") -> Kamis | J3: =TEXT(J4,"dddd") -> Jumat | ... AG3: =TEXT(AG4,"dddd") -> Minggu | AH3: TOTAL | AI3: STOCK | AJ3: SYSTEM | AK3: KET/SELISIH | AL3: HARGA BELI | AM3: HARGA JUAL | AN3: OMSET | AO3: PROFIT | AP3: TOTAL MODAL
C4: =AQ1 -> 45870 | D4: =IF(AND(MONTH(C4+1) = MONTH(C4), C4<>""),C4 + 1, "") -> 45871 | E4: =IF(AND(MONTH(D4+1) = MONTH(D4), D4<>""),D4 + 1, "") -> 45872 | F4: =IF(AND(MONTH(E4+1) = MONTH(E4), E4<>""),E4 + 1, "") -> 45873 | G4: =IF(AND(MONTH(F4+1) = MONTH(F4), F4<>""),F4 + 1, "") -> 45874 | H4: =IF(AND(MONTH(G4+1) = MONTH(G4), G4<>""),G4 + 1, "") -> 45875 | I4: =IF(AND(MONTH(H4+1) = MONTH(H4), H4<>""),H4 + 1, "") -> 45876 | J4: =IF(AND(MONTH(I4+1) = MONTH(I4), I4<>""),I4 + 1, "") -> 45877 | K4: =IF(AND(MONTH(J4+1) = MONTH(J4), J4<>""),J4 + 1, "") -> 45878 | ... AG4: =IF(AND(MONTH(AF4+1) = MONTH(AF4), AF4<>""),AF4 + 1, "") -> 45900
A5: ='MASTER STOCK'!F2 -> Fitting Gantung | B5: ='JULI 25'!AJ5:AJ362 -> 12 | AH5: =SUM(C5:AG5) -> 0 | AI5: =B5-sum(C5:AG5) -> 12 | AJ5: =B5-AH5 -> 12 | AK5: =AJ5-AI5 -> 0 | AL5: ='MASTER STOCK'!I2 -> 1400 | AM5: ='MASTER STOCK'!L2 -> 1820 | AN5: =AH5*AM5 -> 0 | AO5: =AN5-(AH5*AL5) -> 0 | AP5: =AH5*AL5 -> 0
A6: ='MASTER STOCK'!F3 -> Colokan T | B6: ='JULI 25'!AJ6:AJ363 -> 12 | AH6: =SUM(C6:AG6) -> 0 | AI6: =B6-sum(C6:AG6) -> 12 | AJ6: =B6-AH6 -> 12 | AK6: =AJ6-AI6 -> 0 | AL6: ='MASTER STOCK'!I3 -> 3000 | AM6: ='MASTER STOCK'!L3 -> 3900 | AN6: =AH6*AM6 -> 0 | AO6: =AN6-(AH6*AL6) -> 0 | AP6: =AH6*AL6 -> 0
A7: ='MASTER STOCK'!F4 -> Steker Bulat | B7: ='JULI 25'!AJ7:AJ364 -> 12 | AH7: =SUM(C7:AG7) -> 0 | AI7: =B7-sum(C7:AG7) -> 12 | AJ7: =B7-AH7 -> 12 | AK7: =AJ7-AI7 -> 0 | AL7: ='MASTER STOCK'!I4 -> 3000 | AM7: ='MASTER STOCK'!L4 -> 6000 | AN7: =AH7*AM7 -> 0 | AO7: =AN7-(AH7*AL7) -> 0 | AP7: =AH7*AL7 -> 0
A8: ='MASTER STOCK'!F5 -> Steker Gepeng | B8: ='JULI 25'!AJ8:AJ365 -> 12 | AH8: =SUM(C8:AG8) -> 0 | AI8: =B8-sum(C8:AG8) -> 12 | AJ8: =B8-AH8 -> 12 | AK8: =AJ8-AI8 -> 0 | AL8: ='MASTER STOCK'!I5 -> 1100 | AM8: ='MASTER STOCK'!L5 -> 1430 | AN8: =AH8*AM8 -> 0 | AO8: =AN8-(AH8*AL8) -> 0 | AP8: =AH8*AL8 -> 0
A9: ='MASTER STOCK'!F6 -> Saklar Gantung Putih jumbo | B9: ='JULI 25'!AJ9:AJ366 -> 12 | AH9: =SUM(C9:AG9) -> 0 | AI9: =B9-sum(C9:AG9) -> 12 | AJ9: =B9-AH9 -> 12 | AK9: =AJ9-AI9 -> 0 | AL9: ='MASTER STOCK'!I6 -> 2250 | AM9: ='MASTER STOCK'!L6 -> 4000 | AN9: =AH9*AM9 -> 0 | AO9: =AN9-(AH9*AL9) -> 0 | AP9: =AH9*AL9 -> 0
A10: ='MASTER STOCK'!F7 -> Saklar Gantung Hitam | B10: ='JULI 25'!AJ10:AJ367 -> 12 | AH10: =SUM(C10:AG10) -> 0 | AI10: =B10-sum(C10:AG10) -> 12 | AJ10: =B10-AH10 -> 12 | AK10: =AJ10-AI10 -> 0 | AL10: ='MASTER STOCK'!I7 -> 1850 | AM10: ='MASTER STOCK'!L7 -> 4000 | AN10: =AH10*AM10 -> 0 | AO10: =AN10-(AH10*AL10) -> 0 | AP10: =AH10*AL10 -> 0
A11: ='MASTER STOCK'!F8 -> Isolasi Hitam National | B11: ='JULI 25'!AJ11:AJ368 -> 20 | AH11: =SUM(C11:AG11) -> 0 | AI11: =B11-sum(C11:AG11) -> 20 | AJ11: =B11-AH11 -> 20 | AK11: =AJ11-AI11 -> 0 | AL11: ='MASTER STOCK'!I8 -> 5150 | AM11: ='MASTER STOCK'!L8 -> 7982.5 | AN11: =AH11*AM11 -> 0 | AO11: =AN11-(AH11*AL11) -> 0 | AP11: =AH11*AL11 -> 0
A12: ='MASTER STOCK'!F9 -> Lem PVC Isarplas 40gram | B12: ='JULI 25'!AJ12:AJ369 -> 24 | S12: 1 | AH12: =SUM(C12:AG12) -> 1 | AI12: =B12-sum(C12:AG12) -> 23 | AJ12: =B12-AH12 -> 23 | AK12: =AJ12-AI12 -> 0 | AL12: ='MASTER STOCK'!I9 -> 6900 | AM12: ='MASTER STOCK'!L9 -> 9500 | AN12: =AH12*AM12 -> 9500 | AO12: =AN12-(AH12*AL12) -> 2600 | AP12: =AH12*AL12 -> 6900
A13: ='MASTER STOCK'!F10 -> Isolasi Kran air onda | B13: ='JULI 25'!AJ13:AJ370 -> 60 | AH13: =SUM(C13:AG13) -> 0 | AI13: =B13-sum(C13:AG13) -> 60 | AJ13: =B13-AH13 -> 60 | AK13: =AJ13-AI13 -> 0 | AL13: ='MASTER STOCK'!I10 -> 1150 | AM13: ='MASTER STOCK'!L10 -> 1495 | AN13: =AH13*AM13 -> 0 | AO13: =AN13-(AH13*AL13) -> 0 | AP13: =AH13*AL13 -> 0
A14: ='MASTER STOCK'!F11 -> Tutup Pipa 3/4" | B14: ='JULI 25'!AJ14:AJ371 -> 50 | AH14: =SUM(C14:AG14) -> 0 | AI14: =B14-sum(C14:AG14) -> 50 | AJ14: =B14-AH14 -> 50 | AK14: =AJ14-AI14 -> 0 | AL14: ='MASTER STOCK'!I11 -> 850 | AM14: ='MASTER STOCK'!L11 -> 1275 | AN14: =AH14*AM14 -> 0 | AO14: =AN14-(AH14*AL14) -> 0 | AP14: =AH14*AL14 -> 0
A15: ='MASTER STOCK'!F12 -> Fitting lampu gantung outdoor (10 m 5 fitting) | B15: ='JULI 25'!AJ15:AJ372 -> 1 | AH15: =SUM(C15:AG15) -> 0 | AI15: =B15-sum(C15:AG15) -> 1 | AJ15: =B15-AH15 -> 1 | AK15: =AJ15-AI15 -> 0 | AL15: ='MASTER STOCK'!I12 -> 38000 | AM15: ='MASTER STOCK'!L12 -> 49400 | AN15: =AH15*AM15 -> 0 | AO15: =AN15-(AH15*AL15) -> 0 | AP15: =AH15*AL15 -> 0
A16: ='MASTER STOCK'!F13 -> Obeng karet 4" plus | B16: ='JULI 25'!AJ16:AJ373 -> 5 | AH16: =SUM(C16:AG16) -> 0 | AI16: =B16-sum(C16:AG16) -> 5 | AJ16: =B16-AH16 -> 5 | AK16: =AJ16-AI16 -> 0 | AL16: ='MASTER STOCK'!I13 -> 5500 | AM16: ='MASTER STOCK'!L13 -> 7150 | AN16: =AH16*AM16 -> 0 | AO16: =AN16-(AH16*AL16) -> 0 | AP16: =AH16*AL16 -> 0
A17: ='MASTER STOCK'!F14 -> Obeng karet 4" minus | B17: ='JULI 25'!AJ17:AJ374 -> 4 | AH17: =SUM(C17:AG17) -> 0 | AI17: =B17-sum(C17:AG17) -> 4 | AJ17: =B17-AH17 -> 4 | AK17: =AJ17-AI17 -> 0 | AL17: ='MASTER STOCK'!I14 -> 5500 | AM17: ='MASTER STOCK'!L14 -> 7150 | AN17: =AH17*AM17 -> 0 | AO17: =AN17-(AH17*AL17) -> 0 | AP17: =AH17*AL17 -> 0
A18: ='MASTER STOCK'!F15 -> Obeng karet 6" plus | B18: ='JULI 25'!AJ18:AJ375 -> 5 | AH18: =SUM(C18:AG18) -> 0 | AI18: =B18-sum(C18:AG18) -> 5 | AJ18: =B18-AH18 -> 5 | AK18: =AJ18-AI18 -> 0 | AL18: ='MASTER STOCK'!I15 -> 7000 | AM18: ='MASTER STOCK'!L15 -> 9100 | AN18: =AH18*AM18 -> 0 | AO18: =AN18-(AH18*AL18) -> 0 | AP18: =AH18*AL18 -> 0
A19: ='MASTER STOCK'!F16 -> Obeng karet 6" Minus | B19: ='JULI 25'!AJ19:AJ376 -> 5 | AH19: =SUM(C19:AG19) -> 0 | AI19: =B19-sum(C19:AG19) -> 5 | AJ19: =B19-AH19 -> 5 | AK19: =AJ19-AI19 -> 0 | AL19: ='MASTER STOCK'!I16 -> 7000 | AM19: ='MASTER STOCK'!L16 -> 9100 | AN19: =AH19*AM19 -> 0 | AO19: =AN19-(AH19*AL19) -> 0 | AP19: =AH19*AL19 -> 0
A20: ='MASTER STOCK'!F17 -> Kabel Awg 24 Double 2x18 merah hitam | B20: ='JULI 25'!AJ20:AJ377 -> 2 | AH20: =SUM(C20:AG20) -> 0 | AI20: =B20-sum(C20:AG20) -> 2 | AJ20: =B20-AH20 -> 2 | AK20: =AJ20-AI20 -> 0 | AL20: ='MASTER STOCK'!I17 -> 106500 | AM20: ='MASTER STOCK'!L17 -> 181050 | AN20: =AH20*AM20 -> 0 | AO20: =AN20-(AH20*AL20) -> 0 | AP20: =AH20*AL20 -> 0
A21: ='MASTER STOCK'!F18 -> Kabel bintik serabut tembaga motor mobil 20mx0.5mm/0,85mm merah 0,5mm | B21: ='JULI 25'!AJ21:AJ378 -> 2 | AH21: =SUM(C21:AG21) -> 0 | AI21: =B21-sum(C21:AG21) -> 2 | AJ21: =B21-AH21 -> 2 | AK21: =AJ21-AI21 -> 0 | AL21: ='MASTER STOCK'!I18 -> 33700 | AM21: ='MASTER STOCK'!L18 -> 57290 | AN21: =AH21*AM21 -> 0 | AO21: =AN21-(AH21*AL21) -> 0 | AP21: =AH21*AL21 -> 0
A22: ='MASTER STOCK'!F19 -> Kabel bintik serabut tembaga motor mobil 20mx0.5mm/0,85mm hitam 0,5mm | B22: ='JULI 25'!AJ22:AJ379 -> 2 | AH22: =SUM(C22:AG22) -> 0 | AI22: =B22-sum(C22:AG22) -> 2 | AJ22: =B22-AH22 -> 2 | AK22: =AJ22-AI22 -> 0 | AL22: ='MASTER STOCK'!I19 -> 33700 | AM22: ='MASTER STOCK'!L19 -> 57290 | AN22: =AH22*AM22 -> 0 | AO22: =AN22-(AH22*AL22) -> 0 | AP22: =AH22*AL22 -> 0
A23: ='MASTER STOCK'!F20 -> Mata Gerinda keramik 4 inch kering | B23: ='JULI 25'!AJ23:AJ380 -> 5 | AH23: =SUM(C23:AG23) -> 0 | AI23: =B23-sum(C23:AG23) -> 5 | AJ23: =B23-AH23 -> 5 | AK23: =AJ23-AI23 -> 0 | AL23: ='MASTER STOCK'!I20 -> 12000 | AM23: ='MASTER STOCK'!L20 -> 18000 | AN23: =AH23*AM23 -> 0 | AO23: =AN23-(AH23*AL23) -> 0 | AP23: =AH23*AL23 -> 0
A24: ='MASTER STOCK'!F21 -> Kabel tunggal serabut 0.8mmx25m biru 25m | B24: ='JULI 25'!AJ24:AJ381 -> 1 | AH24: =SUM(C24:AG24) -> 0 | AI24: =B24-sum(C24:AG24) -> 1 | AJ24: =B24-AH24 -> 1 | AK24: =AJ24-AI24 -> 0 | AL24: ='MASTER STOCK'!I21 -> 17500 | AM24: ='MASTER STOCK'!L21 -> 29750 | AN24: =AH24*AM24 -> 0 | AO24: =AN24-(AH24*AL24) -> 0 | AP24: =AH24*AL24 -> 0
... A27: ='MASTER STOCK'!F24 -> Lampu LED strip outdoor rainbow 10m +adaptor | B27: ='JULI 25'!AJ27:AJ384 -> 5 | AH27: =SUM(C27:AG27) -> 0 | AI27: =B27-sum(C27:AG27) -> 5 | AJ27: =B27-AH27 -> 5 | AK27: =AJ27-AI27 -> 0 | AL27: ='MASTER STOCK'!I24 -> 27000 | AM27: ='MASTER STOCK'!L24 -> 35100 | AN27: =AH27*AM27 -> 0 | AO27: =AN27-(AH27*AL27) -> 0 | AP27: =AH27*AL27 -> 0
A28: ='MASTER STOCK'!F25 -> Lampu LED strip outdoor merah putih 10m +adaptor | B28: ='JULI 25'!AJ28:AJ385 -> 5 | T28: 1 | AH28: =SUM(C28:AG28) -> 1 | AI28: =B28-sum(C28:AG28) -> 4 | AJ28: =B28-AH28 -> 4 | AK28: =AJ28-AI28 -> 0 | AL28: ='MASTER STOCK'!I25 -> 30000 | AM28: ='MASTER STOCK'!L25 -> 40500 | AN28: =AH28*AM28 -> 40500 | AO28: =AN28-(AH28*AL28) -> 10500 | AP28: =AH28*AL28 -> 30000
A29: ='MASTER STOCK'!F26 -> Lampu tumbler 10m (rainbow) | B29: ='JULI 25'!AJ29:AJ386 -> 5 | AH29: =SUM(C29:AG29) -> 0 | AI29: =B29-sum(C29:AG29) -> 5 | AJ29: =B29-AH29 -> 5 | AK29: =AJ29-AI29 -> 0 | AL29: ='MASTER STOCK'!I26 -> 11000 | AM29: ='MASTER STOCK'!L26 -> 14300 | AN29: =AH29*AM29 -> 0 | AO29: =AN29-(AH29*AL29) -> 0 | AP29: =AH29*AL29 -> 0
A30: ='MASTER STOCK'!F27 -> WD Gerinda potong besi | B30: ='JULI 25'!AJ30:AJ387 -> 58 | AH30: =SUM(C30:AG30) -> 0 | AI30: =B30-sum(C30:AG30) -> 58 | AJ30: =B30-AH30 -> 58 | AK30: =AJ30-AI30 -> 0 | AL30: ='MASTER STOCK'!I27 -> 2900 | AM30: ='MASTER STOCK'!L27 -> 5000 | AN30: =AH30*AM30 -> 0 | AO30: =AN30-(AH30*AL30) -> 0 | AP30: =AH30*AL30 -> 0
A31: ='MASTER STOCK'!F28 -> Meteran karet 7,5m (merk HPP) | B31: ='JULI 25'!AJ31:AJ388 -> 3 | AH31: =SUM(C31:AG31) -> 0 | AI31: =B31-sum(C31:AG31) -> 3 | AJ31: =B31-AH31 -> 3 | AK31: =AJ31-AI31 -> 0 | AL31: ='MASTER STOCK'!I28 -> 12800 | AM31: ='MASTER STOCK'!L28 -> 16640 | AN31: =AH31*AM31 -> 0 | AO31: =AN31-(AH31*AL31) -> 0 | AP31: =AH31*AL31 -> 0
A32: ='MASTER STOCK'!F29 -> Meteran karet 5m (merk VPR) | B32: ='JULI 25'!AJ32:AJ389 -> 3 | AH32: =SUM(C32:AG32) -> 0 | AI32: =B32-sum(C32:AG32) -> 3 | AJ32: =B32-AH32 -> 3 | AK32: =AJ32-AI32 -> 0 | AL32: ='MASTER STOCK'!I29 -> 7000 | AM32: ='MASTER STOCK'!L29 -> 9100 | AN32: =AH32*AM32 -> 0 | AO32: =AN32-(AH32*AL32) -> 0 | AP32: =AH32*AL32 -> 0
A33: ='MASTER STOCK'!F30 -> Kuas cat 2 1/2" (merk MDN) | B33: ='JULI 25'!AJ33:AJ390 -> 5 | AH33: =SUM(C33:AG33) -> 0 | AI33: =B33-sum(C33:AG33) -> 5 | AJ33: =B33-AH33 -> 5 | AK33: =AJ33-AI33 -> 0 | AL33: ='MASTER STOCK'!I30 -> 5300 | AM33: ='MASTER STOCK'!L30 -> 6890 | AN33: =AH33*AM33 -> 0 | AO33: =AN33-(AH33*AL33) -> 0 | AP33: =AH33*AL33 -> 0
A34: ='MASTER STOCK'!F31 -> Kuas cat 2" (merk MDN) | B34: ='JULI 25'!AJ34:AJ391 -> 5 | AH34: =SUM(C34:AG34) -> 0 | AI34: =B34-sum(C34:AG34) -> 5 | AJ34: =B34-AH34 -> 5 | AK34: =AJ34-AI34 -> 0 | AL34: ='MASTER STOCK'!I31 -> 4400 | AM34: ='MASTER STOCK'!L31 -> 5720 | AN34: =AH34*AM34 -> 0 | AO34: =AN34-(AH34*AL34) -> 0 | AP34: =AH34*AL34 -> 0
A35: ='MASTER STOCK'!F32 -> Kuas cat 3" (merk MDN) | B35: ='JULI 25'!AJ35:AJ392 -> 5 | T35: 1 | AH35: =SUM(C35:AG35) -> 1 | AI35: =B35-sum(C35:AG35) -> 4 | AJ35: =B35-AH35 -> 4 | AK35: =AJ35-AI35 -> 0 | AL35: ='MASTER STOCK'!I32 -> 6300 | AM35: ='MASTER STOCK'!L32 -> 8190 | AN35: =AH35*AM35 -> 8190 | AO35: =AN35-(AH35*AL35) -> 1890 | AP35: =AH35*AL35 -> 6300
A36: ='MASTER STOCK'!F33 -> Kuas cat 1 1/2" (merk MDN) | B36: ='JULI 25'!AJ36:AJ393 -> 5 | AH36: =SUM(C36:AG36) -> 0 | AI36: =B36-sum(C36:AG36) -> 5 | AJ36: =B36-AH36 -> 5 | AK36: =AJ36-AI36 -> 0 | AL36: ='MASTER STOCK'!I33 -> 3400 | AM36: ='MASTER STOCK'!L33 -> 4420 | AN36: =AH36*AM36 -> 0 | AO36: =AN36-(AH36*AL36) -> 0 | AP36: =AH36*AL36 -> 0
A37: ='MASTER STOCK'!F34 -> Kuas cat 1" (merk MDN) | B37: ='JULI 25'!AJ37:AJ394 -> 5 | T37: 1 | AH37: =SUM(C37:AG37) -> 1 | AI37: =B37-sum(C37:AG37) -> 4 | AJ37: =B37-AH37 -> 4 | AK37: =AJ37-AI37 -> 0 | AL37: ='MASTER STOCK'!I34 -> 2300 | AM37: ='MASTER STOCK'!L34 -> 2990 | AN37: =AH37*AM37 -> 2990 | AO37: =AN37-(AH37*AL37) -> 690 | AP37: =AH37*AL37 -> 2300
A38: ='MASTER STOCK'!F35 -> Kran PVC Tembok 3/4" | B38: ='JULI 25'!AJ38:AJ395 -> 24 | AH38: =SUM(C38:AG38) -> 0 | AI38: =B38-sum(C38:AG38) -> 24 | AJ38: =B38-AH38 -> 24 | AK38: =AJ38-AI38 -> 0 | AL38: ='MASTER STOCK'!I35 -> 4200 | AM38: ='MASTER STOCK'!L35 -> 6000 | AN38: =AH38*AM38 -> 0 | AO38: =AN38-(AH38*AL38) -> 0 | AP38: =AH38*AL38 -> 0
A39: ='MASTER STOCK'!F36 -> Kran PVC Tembok 1/2" | B39: ='JULI 25'!AJ39:AJ396 -> 24 | AH39: =SUM(C39:AG39) -> 0 | AI39: =B39-sum(C39:AG39) -> 24 | AJ39: =B39-AH39 -> 24 | AK39: =AJ39-AI39 -> 0 | AL39: ='MASTER STOCK'!I36 -> 4200 | AM39: ='MASTER STOCK'!L36 -> 6000 | AN39: =AH39*AM39 -> 0 | AO39: =AN39-(AH39*AL39) -> 0 | AP39: =AH39*AL39 -> 0
A40: ='MASTER STOCK'!F37 -> Lampu bohlam inlite 5w Putih | B40: ='JULI 25'!AJ40:AJ397 -> 7 | AH40: =SUM(C40:AG40) -> 0 | AI40: =B40-sum(C40:AG40) -> 7 | AJ40: =B40-AH40 -> 7 | AK40: =AJ40-AI40 -> 0 | AL40: ='MASTER STOCK'!I37 -> 13000 | AM40: ='MASTER STOCK'!L37 -> 18200 | AN40: =AH40*AM40 -> 0 | AO40: =AN40-(AH40*AL40) -> 0 | AP40: =AH40*AL40 -> 0
A41: ='MASTER STOCK'!F38 -> Lampu bohlam inlite 7w Putih | B41: ='JULI 25'!AJ41:AJ398 -> 2 | AH41: =SUM(C41:AG41) -> 0 | AI41: =B41-sum(C41:AG41) -> 2 | AJ41: =B41-AH41 -> 2 | AK41: =AJ41-AI41 -> 0 | AL41: ='MASTER STOCK'!I38 -> 16200 | AM41: ='MASTER STOCK'!L38 -> 22680 | AN41: =AH41*AM41 -> 0 | AO41: =AN41-(AH41*AL41) -> 0 | AP41: =AH41*AL41 -> 0
A42: ='MASTER STOCK'!F39 -> Lampu bohlam inlite 15w Putih | B42: ='JULI 25'!AJ42:AJ399 -> 4 | AH42: =SUM(C42:AG42) -> 0 | AI42: =B42-sum(C42:AG42) -> 4 | AJ42: =B42-AH42 -> 4 | AK42: =AJ42-AI42 -> 0 | AL42: ='MASTER STOCK'!I39 -> 28000 | AM42: ='MASTER STOCK'!L39 -> 39200 | AN42: =AH42*AM42 -> 0 | AO42: =AN42-(AH42*AL42) -> 0 | AP42: =AH42*AL42 -> 0
...

Sheet SEP 25
A1: LAPORAN PENJUALAN BULANAN | AQ1: 45901
A2: NAMA BARANG | B2: STOK AWAL | C2: =UPPER("HARI / BULAN : " & TEXT(AQ1, "MMMM YYYY")) -> HARI / BULAN : SEPTEMBER 2025
C3: =TEXT(C4,"dddd") -> Senin | D3: =TEXT(D4,"dddd") -> Selasa | E3: =TEXT(E4,"dddd") -> Rabu | F3: =TEXT(F4,"dddd") -> Kamis | G3: =TEXT(G4,"dddd") -> Jumat | H3: =TEXT(H4,"dddd") -> Sabtu | I3: =TEXT(I4,"dddd") -> Minggu | J3: =TEXT(J4,"dddd") -> Senin | ... AG3: =TEXT(AG4,"dddd") | AH3: TOTAL | AI3: STOCK | AJ3: SYSTEM | AK3: KET/SELISIH | AL3: HARGA BELI | AM3: HARGA JUAL | AN3: OMSET | AO3: PROFIT | AP3: TOTAL MODAL
C4: =AQ1 -> 45901 | D4: =IF(AND(MONTH(C4+1) = MONTH(C4), C4<>""),C4 + 1, "") -> 45902 | E4: =IF(AND(MONTH(D4+1) = MONTH(D4), D4<>""),D4 + 1, "") -> 45903 | F4: =IF(AND(MONTH(E4+1) = MONTH(E4), E4<>""),E4 + 1, "") -> 45904 | G4: =IF(AND(MONTH(F4+1) = MONTH(F4), F4<>""),F4 + 1, "") -> 45905 | H4: =IF(AND(MONTH(G4+1) = MONTH(G4), G4<>""),G4 + 1, "") -> 45906 | I4: =IF(AND(MONTH(H4+1) = MONTH(H4), H4<>""),H4 + 1, "") -> 45907 | J4: =IF(AND(MONTH(I4+1) = MONTH(I4), I4<>""),I4 + 1, "") -> 45908 | K4: =IF(AND(MONTH(J4+1) = MONTH(J4), J4<>""),J4 + 1, "") -> 45909 | ... AG4: =IF(AND(MONTH(AF4+1) = MONTH(AF4), AF4<>""),AF4 + 1, "")
A5: ='MASTER STOCK'!F2 -> Fitting Gantung | B5: ='AGS 25'!AJ5:AJ367 -> 12 | G5: 2 | AH5: =SUM(C5:AG5) -> 2 | AI5: 0 | AJ5: =B5-AH5 -> 10 | AK5: =AJ5-AI5 -> 10 | AL5: ='MASTER STOCK'!I2 -> 1400 | AM5: ='MASTER STOCK'!L2 -> 1820 | AN5: =AH5*AM5 -> 3640 | AO5: =AN5-(AH5*AL5) -> 840 | AP5: =AH5*AL5 -> 2800
A6: ='MASTER STOCK'!F3 -> Colokan T | B6: ='AGS 25'!AJ6:AJ368 -> 12 | H6: 1 | AH6: =SUM(C6:AG6) -> 1 | AI6: 0 | AJ6: =B6-AH6 -> 11 | AK6: =AJ6-AI6 -> 11 | AL6: ='MASTER STOCK'!I3 -> 3000 | AM6: ='MASTER STOCK'!L3 -> 3900 | AN6: =AH6*AM6 -> 3900 | AO6: =AN6-(AH6*AL6) -> 900 | AP6: =AH6*AL6 -> 3000
A7: ='MASTER STOCK'!F4 -> Steker Bulat | B7: ='AGS 25'!AJ7:AJ369 -> 12 | AH7: =SUM(C7:AG7) -> 0 | AI7: 0 | AJ7: =B7-AH7 -> 12 | AK7: =AJ7-AI7 -> 12 | AL7: ='MASTER STOCK'!I4 -> 3000 | AM7: ='MASTER STOCK'!L4 -> 6000 | AN7: =AH7*AM7 -> 0 | AO7: =AN7-(AH7*AL7) -> 0 | AP7: =AH7*AL7 -> 0
A8: ='MASTER STOCK'!F5 -> Steker Gepeng | B8: ='AGS 25'!AJ8:AJ370 -> 12 | AH8: =SUM(C8:AG8) -> 0 | AI8: 0 | AJ8: =B8-AH8 -> 12 | AK8: =AJ8-AI8 -> 12 | AL8: ='MASTER STOCK'!I5 -> 1100 | AM8: ='MASTER STOCK'!L5 -> 1430 | AN8: =AH8*AM8 -> 0 | AO8: =AN8-(AH8*AL8) -> 0 | AP8: =AH8*AL8 -> 0
A9: ='MASTER STOCK'!F6 -> Saklar Gantung Putih jumbo | B9: ='AGS 25'!AJ9:AJ371 -> 12 | G9: 2 | V9: 1 | AH9: =SUM(C9:AG9) -> 3 | AI9: 0 | AJ9: =B9-AH9 -> 9 | AK9: =AJ9-AI9 -> 9 | AL9: ='MASTER STOCK'!I6 -> 2250 | AM9: ='MASTER STOCK'!L6 -> 4000 | AN9: =AH9*AM9 -> 12000 | AO9: =AN9-(AH9*AL9) -> 5250 | AP9: =AH9*AL9 -> 6750
A10: ='MASTER STOCK'!F7 -> Saklar Gantung Hitam | B10: ='AGS 25'!AJ10:AJ372 -> 12 | AH10: =SUM(C10:AG10) -> 0 | AI10: 0 | AJ10: =B10-AH10 -> 12 | AK10: =AJ10-AI10 -> 12 | AL10: ='MASTER STOCK'!I7 -> 1850 | AM10: ='MASTER STOCK'!L7 -> 4000 | AN10: =AH10*AM10 -> 0 | AO10: =AN10-(AH10*AL10) -> 0 | AP10: =AH10*AL10 -> 0
A11: ='MASTER STOCK'!F8 -> Isolasi Hitam National | B11: ='AGS 25'!AJ11:AJ373 -> 20 | G11: 1 | AH11: =SUM(C11:AG11) -> 1 | AI11: 0 | AJ11: =B11-AH11 -> 19 | AK11: =AJ11-AI11 -> 19 | AL11: ='MASTER STOCK'!I8 -> 5150 | AM11: ='MASTER STOCK'!L8 -> 7982.5 | AN11: =AH11*AM11 -> 7982.5 | AO11: =AN11-(AH11*AL11) -> 2832.5 | AP11: =AH11*AL11 -> 5150
A12: ='MASTER STOCK'!F9 -> Lem PVC Isarplas 40gram | B12: ='AGS 25'!AJ12:AJ374 -> 23 | Y12: 1 | AH12: =SUM(C12:AG12) -> 1 | AI12: 0 | AJ12: =B12-AH12 -> 22 | AK12: =AJ12-AI12 -> 22 | AL12: ='MASTER STOCK'!I9 -> 6900 | AM12: ='MASTER STOCK'!L9 -> 9500 | AN12: =AH12*AM12 -> 9500 | AO12: =AN12-(AH12*AL12) -> 2600 | AP12: =AH12*AL12 -> 6900
A13: ='MASTER STOCK'!F10 -> Isolasi Kran air onda | B13: ='AGS 25'!AJ13:AJ375 -> 60 | AH13: =SUM(C13:AG13) -> 0 | AI13: 0 | AJ13: =B13-AH13 -> 60 | AK13: =AJ13-AI13 -> 60 | AL13: ='MASTER STOCK'!I10 -> 1150 | AM13: ='MASTER STOCK'!L10 -> 1495 | AN13: =AH13*AM13 -> 0 | AO13: =AN13-(AH13*AL13) -> 0 | AP13: =AH13*AL13 -> 0
A14: ='MASTER STOCK'!F11 -> Tutup Pipa 3/4" | B14: ='AGS 25'!AJ14:AJ376 -> 50 | AH14: =SUM(C14:AG14) -> 0 | AI14: 0 | AJ14: =B14-AH14 -> 50 | AK14: =AJ14-AI14 -> 50 | AL14: ='MASTER STOCK'!I11 -> 850 | AM14: ='MASTER STOCK'!L11 -> 1275 | AN14: =AH14*AM14 -> 0 | AO14: =AN14-(AH14*AL14) -> 0 | AP14: =AH14*AL14 -> 0
A15: ='MASTER STOCK'!F12 -> Fitting lampu gantung outdoor (10 m 5 fitting) | B15: ='AGS 25'!AJ15:AJ377 -> 1 | AH15: =SUM(C15:AG15) -> 0 | AI15: 0 | AJ15: =B15-AH15 -> 1 | AK15: =AJ15-AI15 -> 1 | AL15: ='MASTER STOCK'!I12 -> 38000 | AM15: ='MASTER STOCK'!L12 -> 49400 | AN15: =AH15*AM15 -> 0 | AO15: =AN15-(AH15*AL15) -> 0 | AP15: =AH15*AL15 -> 0
A16: ='MASTER STOCK'!F13 -> Obeng karet 4" plus | B16: ='AGS 25'!AJ16:AJ378 -> 5 | AH16: =SUM(C16:AG16) -> 0 | AI16: 0 | AJ16: =B16-AH16 -> 5 | AK16: =AJ16-AI16 -> 5 | AL16: ='MASTER STOCK'!I13 -> 5500 | AM16: ='MASTER STOCK'!L13 -> 7150 | AN16: =AH16*AM16 -> 0 | AO16: =AN16-(AH16*AL16) -> 0 | AP16: =AH16*AL16 -> 0
A17: ='MASTER STOCK'!F14 -> Obeng karet 4" minus | B17: ='AGS 25'!AJ17:AJ379 -> 4 | AH17: =SUM(C17:AG17) -> 0 | AI17: 0 | AJ17: =B17-AH17 -> 4 | AK17: =AJ17-AI17 -> 4 | AL17: ='MASTER STOCK'!I14 -> 5500 | AM17: ='MASTER STOCK'!L14 -> 7150 | AN17: =AH17*AM17 -> 0 | AO17: =AN17-(AH17*AL17) -> 0 | AP17: =AH17*AL17 -> 0
A18: ='MASTER STOCK'!F15 -> Obeng karet 6" plus | B18: ='AGS 25'!AJ18:AJ380 -> 5 | AH18: =SUM(C18:AG18) -> 0 | AI18: 0 | AJ18: =B18-AH18 -> 5 | AK18: =AJ18-AI18 -> 5 | AL18: ='MASTER STOCK'!I15 -> 7000 | AM18: ='MASTER STOCK'!L15 -> 9100 | AN18: =AH18*AM18 -> 0 | AO18: =AN18-(AH18*AL18) -> 0 | AP18: =AH18*AL18 -> 0
A19: ='MASTER STOCK'!F16 -> Obeng karet 6" Minus | B19: ='AGS 25'!AJ19:AJ381 -> 5 | AH19: =SUM(C19:AG19) -> 0 | AI19: 0 | AJ19: =B19-AH19 -> 5 | AK19: =AJ19-AI19 -> 5 | AL19: ='MASTER STOCK'!I16 -> 7000 | AM19: ='MASTER STOCK'!L16 -> 9100 | AN19: =AH19*AM19 -> 0 | AO19: =AN19-(AH19*AL19) -> 0 | AP19: =AH19*AL19 -> 0
A20: ='MASTER STOCK'!F17 -> Kabel Awg 24 Double 2x18 merah hitam | B20: ='AGS 25'!AJ20:AJ382 -> 2 | AH20: =SUM(C20:AG20) -> 0 | AI20: 0 | AJ20: =B20-AH20 -> 2 | AK20: =AJ20-AI20 -> 2 | AL20: ='MASTER STOCK'!I17 -> 106500 | AM20: ='MASTER STOCK'!L17 -> 181050 | AN20: =AH20*AM20 -> 0 | AO20: =AN20-(AH20*AL20) -> 0 | AP20: =AH20*AL20 -> 0
A21: ='MASTER STOCK'!F18 -> Kabel bintik serabut tembaga motor mobil 20mx0.5mm/0,85mm merah 0,5mm | B21: ='AGS 25'!AJ21:AJ383 -> 2 | Q21: 1 | AH21: =SUM(C21:AG21) -> 1 | AI21: 0 | AJ21: =B21-AH21 -> 1 | AK21: =AJ21-AI21 -> 1 | AL21: ='MASTER STOCK'!I18 -> 33700 | AM21: ='MASTER STOCK'!L18 -> 57290 | AN21: =AH21*AM21 -> 57290 | AO21: =AN21-(AH21*AL21) -> 23590 | AP21: =AH21*AL21 -> 33700
A22: ='MASTER STOCK'!F19 -> Kabel bintik serabut tembaga motor mobil 20mx0.5mm/0,85mm hitam 0,5mm | B22: ='AGS 25'!AJ22:AJ384 -> 2 | Q22: 1 | AH22: =SUM(C22:AG22) -> 1 | AI22: 0 | AJ22: =B22-AH22 -> 1 | AK22: =AJ22-AI22 -> 1 | AL22: ='MASTER STOCK'!I19 -> 33700 | AM22: ='MASTER STOCK'!L19 -> 57290 | AN22: =AH22*AM22 -> 57290 | AO22: =AN22-(AH22*AL22) -> 23590 | AP22: =AH22*AL22 -> 33700
A23: ='MASTER STOCK'!F20 -> Mata Gerinda keramik 4 inch kering | B23: ='AGS 25'!AJ23:AJ385 -> 5 | AH23: =SUM(C23:AG23) -> 0 | AI23: 0 | AJ23: =B23-AH23 -> 5 | AK23: =AJ23-AI23 -> 5 | AL23: ='MASTER STOCK'!I20 -> 12000 | AM23: ='MASTER STOCK'!L20 -> 18000 | AN23: =AH23*AM23 -> 0 | AO23: =AN23-(AH23*AL23) -> 0 | AP23: =AH23*AL23 -> 0
A24: ='MASTER STOCK'!F21 -> Kabel tunggal serabut 0.8mmx25m biru 25m | B24: ='AGS 25'!AJ24:AJ386 -> 1 | AH24: =SUM(C24:AG24) -> 0 | AI24: 0 | AJ24: =B24-AH24 -> 1 | AK24: =AJ24-AI24 -> 1 | AL24: ='MASTER STOCK'!I21 -> 17500 | AM24: ='MASTER STOCK'!L21 -> 29750 | AN24: =AH24*AM24 -> 0 | AO24: =AN24-(AH24*AL24) -> 0 | AP24: =AH24*AL24 -> 0
A25: ='MASTER STOCK'!F22 -> Kabel tunggal serabut 0.8mmx25m Hitam 25m | B25: ='AGS 25'!AJ25:AJ387 -> 1 | AH25: =SUM(C25:AG25) -> 0 | AI25: 0 | AJ25: =B25-AH25 -> 1 | AK25: =AJ25-AI25 -> 1 | AL25: ='MASTER STOCK'!I22 -> 17500 | AM25: ='MASTER STOCK'!L22 -> 29750 | AN25: =AH25*AM25 -> 0 | AO25: =AN25-(AH25*AL25) -> 0 | AP25: =AH25*AL25 -> 0
A26: ='MASTER STOCK'!F23 -> Lampu Hias LED strip USB 10m+adaptor | B26: ='AGS 25'!AJ26:AJ388 -> 2 | AH26: =SUM(C26:AG26) -> 0 | AI26: 0 | AJ26: =B26-AH26 -> 2 | AK26: =AJ26-AI26 -> 2 | AL26: ='MASTER STOCK'!I23 -> 50000 | AM26: ='MASTER STOCK'!L23 -> 65000 | AN26: =AH26*AM26 -> 0 | AO26: =AN26-(AH26*AL26) -> 0 | AP26: =AH26*AL26 -> 0
A27: ='MASTER STOCK'!F24 -> Lampu LED strip outdoor rainbow 10m +adaptor | B27: ='AGS 25'!AJ27:AJ389 -> 5 | AH27: =SUM(C27:AG27) -> 0 | AI27: 0 | AJ27: =B27-AH27 -> 5 | AK27: =AJ27-AI27 -> 5 | AL27: ='MASTER STOCK'!I24 -> 27000 | AM27: ='MASTER STOCK'!L24 -> 35100 | AN27: =AH27*AM27 -> 0 | AO27: =AN27-(AH27*AL27) -> 0 | AP27: =AH27*AL27 -> 0
A28: ='MASTER STOCK'!F25 -> Lampu LED strip outdoor merah putih 10m +adaptor | B28: ='AGS 25'!AJ28:AJ390 -> 4 | AH28: =SUM(C28:AG28) -> 0 | AI28: 0 | AJ28: =B28-AH28 -> 4 | AK28: =AJ28-AI28 -> 4 | AL28: ='MASTER STOCK'!I25 -> 30000 | AM28: ='MASTER STOCK'!L25 -> 40500 | AN28: =AH28*AM28 -> 0 | AO28: =AN28-(AH28*AL28) -> 0 | AP28: =AH28*AL28 -> 0
